Workbook

Sheet 数学-分数面板
A1: 数学考研面板总分 | B1: =SUM(B3,B21,B35) -> 0
A2: 高等数学（60%，90分）
A3: 总分 | B3: =SUM(F5:V5)*0.01*D5+SUM(F7:X7)*0.01*D7+SUM(F9:P9)*0.01*D9+SUM(F11:Y11)*0.01*D11+SUM(F13:S13)*0.01*D13+SUM(F15:Q15)*0.01*D15+SUM(F17:V17)*0.01*D17+SUM(F19:S19)*0.01*D19 -> 0
A4: 函数，极限，连续 | B4: 小节分数 | C4: 总节点数 | D4: 单节点分数 | E4: 节点 | F4: 函数的概念及表示法 | G4: 函数的有界性、单调性、周期性和奇偶性 | H4: 复合函数、反函数、分段函数和隐函数 | I4: 基本初等函数的性质及其图形 | J4: 初等函数 | K4: 函数关系的建立 | L4: 数列极限与函数极限的定义及其性质 | M4: 函数的左极限和右极限 | N4: 无穷小量和无穷大量的概念及其关系 | O4: 无穷小量的性质及无穷小量的比较 | P4: 极限的四则运算 | Q4: 极限存在的两个准则：单调有界准则和夹逼准则 | R4: 两个重要极限 | S4: 函数连续的概念 | T4: 函数间断点的类型 | U4: 初等函数的连续性 | V4: 闭区间上连续函数的性质
B5: =ROUND('数学-小节得分-2017'!B3*10%+'数学-小节得分-2020'!B3*12.5%+'数学-小节得分-2021'!B3*13.5%+'数学-小节得分-2022'!B3*14.5%+'数学-小节得分-2023'!B3*15.5%+'数学-小节得分-2024'!B3*16.5%+'数学-小节得分-2025'!B3*17.5%,1) -> 9.2 | C5: =COUNTA(F4:Y4) -> 17 | D5: =ROUND(B5/C5,2) -> 0.54 | E5: 掌握度（0~100） | F5: 0 | G5: 0 | H5: 0 | I5: 0 | J5: 0 | K5: 0 | L5: 0 | M5: 0 | N5: 0 | O5: 0 | P5: 0 | Q5: 0 | R5: 0 | S5: 0 | T5: 0 | U5: 0 | V5: 0
A6: 一元函数微分 | B6: 小节分数 | C6: 总节点数 | D6: 单节点分数 | E6: 节点 | F6: 导数和微分的概念 | G6: 导数的几何意义和物理意义 | H6: 函数的可导性与连续性之间的关系 | I6: 平面曲线的切线和法线 | J6: 导数和微分的四则运算 | K6: 基本初等函数的导数 | L6: 复合函数、反函数、隐函数以及参数方程所确定的函数的微分法 | M6: 高阶导数 | N6: 一阶微分形式的不变性 | O6: 微分中值定理 | P6: 洛必达（L’Hospital）法则 | Q6: 函数单调性的判别 | R6: 函数的极值 | S6: 函数图形的凹凸性、拐点及渐近线 | T6: 函数图形的描绘 | U6: 函数的最大值与最小值 | V6: 弧微分 | W6: 曲率的概念 | X6: 曲率圆与曲率半径
B7: =ROUND('数学-小节得分-2017'!B5*10%+'数学-小节得分-2020'!B5*12.5%+'数学-小节得分-2021'!B5*13.5%+'数学-小节得分-2022'!B5*14.5%+'数学-小节得分-2023'!B5*15.5%+'数学-小节得分-2024'!B5*16.5%+'数学-小节得分-2025'!B5*17.5%,1) -> 17.6 | C7: =COUNTA(F6:Y6) -> 19 | D7: =ROUND(B7/C7,2) -> 0.93 | E7: 掌握度（0~100） | F7: 0 | G7: 0 | H7: 0 | I7: 0 | J7: 0 | K7: 0 | L7: 0 | M7: 0 | N7: 0 | O7: 0 | P7: 0 | Q7: 0 | R7: 0 | S7: 0 | T7: 0 | U7: 0 | V7: 0 | W7: 0 | X7: 0
A8: 一元函数积分 | B8: 小节分数 | C8: 总节点数 | D8: 单节点分数 | E8: 节点 | F8: 原函数和不定积分的概念 | G8: 不定积分的基本性质 | H8: 基本积分公式 | I8: 定积分的概念和基本性质 | J8: 定积分中值定理 | K8: 积分上限的函数及其导数 | L8: 牛顿-莱布尼茨（Newton-Leibniz）公式 | M8: 不定积分和定积分的换元积分法与分部积分法 | N8: 有理函数、三角函数有理式和简单无理函数的积分 | O8: 反常（广义）积分 | P8: 定积分的应用
B9: =ROUND('数学-小节得分-2017'!B7*10%+'数学-小节得分-2020'!B7*12.5%+'数学-小节得分-2021'!B7*13.5%+'数学-小节得分-2022'!B7*14.5%+'数学-小节得分-2023'!B7*15.5%+'数学-小节得分-2024'!B7*16.5%+'数学-小节得分-2025'!B7*17.5%,1) -> 9.6 | C9: =COUNTA(F8:Y8) -> 11 | D9: =ROUND(B9/C9,2) -> 0.87 | E9: 掌握度（0~100） | F9: 0 | G9: 0 | H9: 0 | I9: 0 | J9: 0 | K9: 0 | L9: 0 | M9: 0 | N9: 0 | O9: 0 | P9: 0
A10: 向量代数与空间解析几何 | B10: 小节分数 | C10: 总节点数 | D10: 单节点分数 | E10: 节点 | F10: 向量的概念 | G10: 向量的线性运算 | H10: 向量的数量积和向量积 | I10: 向量的混合积 | J10: 两向量垂直、平行的条件 | K10: 两向量的夹角 | L10: 向量的坐标表达式及其运算 | M10: 单位向量 | N10: 方向数与方向余弦 | O10: 曲面方程和空间曲线方程的概念 | P10: 平面方程 | Q10: 直线方程 | R10: 平面与平面、平面与直线、直线与直线的夹角以及平行、垂直的条件 | S10: 点到平面和点到直线的距离 | T10: 球面 | U10: 柱面 | V10: 旋转曲面 | W10: 常用的二次曲面方程及其图形 | X10: 空间曲线的参数方程和一般方程 | Y10: 空间曲线在坐标面上的投影曲线方程
B11: =ROUND('数学-小节得分-2017'!B9*10%+'数学-小节得分-2020'!B9*12.5%+'数学-小节得分-2021'!B9*13.5%+'数学-小节得分-2022'!B9*14.5%+'数学-小节得分-2023'!B9*15.5%+'数学-小节得分-2024'!B9*16.5%+'数学-小节得分-2025'!B9*17.5%,1) -> 3.8 | C11: =COUNTA(F10:Y10) -> 20 | D11: =ROUND(B11/C11,2) -> 0.19 | E11: 掌握度（0~100） | F11: 0 | G11: 0 | H11: 0 | I11: 0 | J11: 0 | K11: 0 | L11: 0 | M11: 0 | N11: 0 | O11: 0 | P11: 0 | Q11: 0 | R11: 0 | S11: 0 | T11: 0 | U11: 0 | V11: 0 | W11: 0 | X11: 0 | Y11: 0
A12: 多元函数微分 | B12: 小节分数 | C12: 总节点数 | D12: 单节点分数 | E12: 节点 | F12: 多元函数的概念 | G12: 二元函数的几何意义 | H12: 二元函数的极限与连续的概念 | I12: 有界闭区域上多元连续函数的性质 | J12: 多元函数的偏导数和全微分 | K12: 全微分存在的必要条件和充分条件 | L12: 多元复合函数、隐函数的求导法 | M12: 二阶偏导数 | N12: 方向导数和梯度 | O12: 空间曲线的切线和法平面 | P12: 曲面的切平面和法线 | Q12: 二元函数的二阶泰勒公式 | R12: 多元函数的极值和条件极值 | S12: 多元函数的最大值、最小值及其简单应用
B13: =ROUND('数学-小节得分-2017'!B11*10%+'数学-小节得分-2020'!B11*12.5%+'数学-小节得分-2021'!B11*13.5%+'数学-小节得分-2022'!B11*14.5%+'数学-小节得分-2023'!B11*15.5%+'数学-小节得分-2024'!B11*16.5%+'数学-小节得分-2025'!B11*17.5%,1) -> 14.2 | C13: =COUNTA(F12:Y12) -> 14 | D13: =ROUND(B13/C13,2) -> 1.01 | E13: 掌握度（0~100） | F13: 0 | G13: 0 | H13: 0 | I13: 0 | J13: 0 | K13: 0 | L13: 0 | M13: 0 | N13: 0 | O13: 0 | P13: 0 | Q13: 0 | R13: 0 | S13: 0
A14: 多元函数积分 | B14: 小节分数 | C14: 总节点数 | D14: 单节点分数 | E14: 节点 | F14: 二重积分与三重积分的概念、性质、计算和应用 | G14: 两类曲线积分的概念、性质及计算 | H14: 两类曲线积分的关系 | I14: 格林（Green）公式 | J14: 平面曲线积分与路径无关的条件 | K14: 二元函数全微分的原函数 | L14: 两类曲面积分的概念、性质及计算 | M14: 两类曲面积分的关系 | N14: 高斯（Gauss）公式 | O14: 斯托克斯（Stokes）公式 | P14: 散度、旋度的概念及计算 | Q14: 曲线积分和曲面积分的应用
B15: =ROUND('数学-小节得分-2017'!B13*10%+'数学-小节得分-2020'!B13*12.5%+'数学-小节得分-2021'!B13*13.5%+'数学-小节得分-2022'!B13*14.5%+'数学-小节得分-2023'!B13*15.5%+'数学-小节得分-2024'!B13*16.5%+'数学-小节得分-2025'!B13*17.5%,1) -> 18 | C15: =COUNTA(F14:Y14) -> 12 | D15: =ROUND(B15/C15,2) -> 1.5 | E15: 掌握度（0~100） | F15: 0 | G15: 0 | H15: 0 | I15: 0 | J15: 0 | K15: 0 | L15: 0 | M15: 0 | N15: 0 | O15: 0 | P15: 0 | Q15: 0
A16: 无穷级数 | B16: 小节分数 | C16: 总节点数 | D16: 单节点分数 | E16: 节点 | F16: 常数项级数的收敛与发散的概念 | G16: 收敛级数的和的概念 | H16: 级数的基本性质与收敛的必要条件 | I16: 几何级数与p级数及其收敛性 | J16: 正项级数收敛性的判别法 | K16: 交错级数与莱布尼茨定理 | L16: 任意项级数的绝对收敛与条件收敛 | M16: 函数项级数的收敛域与和函数的概念 | N16: 幂级数及其收敛半径、收敛区间（指开区间）和收敛域 | O16: 幂级数的和函数 | P16: 幂级数在其收敛区间内的基本性质 | Q16: 简单幂级数的和函数的求法 | R16: 初等函数的幂级数展开式 | S16: 函数的傅里叶（Fourier）系数与傅里叶级数 | T16: 狄利克雷（Dirichlet）定理 | U16: 函数在[-l，l]上的傅里叶级数 | V16: 函数在[0，l]上的正弦级数和余弦级数
B17: =ROUND('数学-小节得分-2017'!B15*10%+'数学-小节得分-2020'!B15*12.5%+'数学-小节得分-2021'!B15*13.5%+'数学-小节得分-2022'!B15*14.5%+'数学-小节得分-2023'!B15*15.5%+'数学-小节得分-2024'!B15*16.5%+'数学-小节得分-2025'!B15*17.5%,1) -> 8.4 | C17: =COUNTA(F16:Y16) -> 17 | D17: =ROUND(B17/C17,2) -> 0.49 | E17: 掌握度（0~100） | F17: 0 | G17: 0 | H17: 0 | I17: 0 | J17: 0 | K17: 0 | L17: 0 | M17: 0 | N17: 0 | O17: 0 | P17: 0 | Q17: 0 | R17: 0 | S17: 0 | T17: 0 | U17: 0 | V17: 0
A18: 常微分方程 | B18: 小节分数 | C18: 总节点数 | D18: 单节点分数 | E18: 节点 | F18: 常微分方程的基本概念 | G18: 变量可分离的微分方程 | H18: 齐次微分方程 | I18: 一阶线性微分方程 | J18: 伯努利（Bernoulli）方程 | K18: 全微分方程 | L18: 可用简单的变量代换求解的某些微分方程 | M18: 可降阶的高阶微分方程 | N18: 线性微分方程解的性质及解的结构定理 | O18: 二阶常系数齐次线性微分方程 | P18: 高于二阶的某些常系数齐次线性微分方程 | Q18: 简单的二阶常系数非齐次线性微分方程 | R18: 欧拉（Euler）方程 | S18: 微分方程的简单应用
B19: =ROUND('数学-小节得分-2017'!B17*10%+'数学-小节得分-2020'!B17*12.5%+'数学-小节得分-2021'!B17*13.5%+'数学-小节得分-2022'!B17*14.5%+'数学-小节得分-2023'!B17*15.5%+'数学-小节得分-2024'!B17*16.5%+'数学-小节得分-2025'!B17*17.5%,1) -> 5.9 | C19: =COUNTA(F18:Y18) -> 14 | D19: =ROUND(B19/C19,2) -> 0.42 | E19: 掌握度（0~100） | F19: 0 | G19: 0 | H19: 0 | I19: 0 | J19: 0 | K19: 0 | L19: 0 | M19: 0 | N19: 0 | O19: 0 | P19: 0 | Q19: 0 | R19: 0 | S19: 0
A20: 线性代数（20%，30分）
A21: 总分 | B21: =SUM(F23:G23)*0.01*D23+SUM(F25:S25)*0.01*D25+SUM(F27:S27)*0.01*D27+SUM(F29:L29)*0.01*D29+SUM(F31:I31)*0.01*D31+SUM(F33:L33)*0.01*D33 -> 0
A22: 行列式 | B22: 小节分数 | C22: 总节点数 | D22: 单节点分数 | E22: 节点 | F22: 行列式的概念和基本性质 | G22: 行列式按行（列）展开定理
B23: =ROUND('数学-小节得分-2017'!B20*10%+'数学-小节得分-2020'!B20*12.5%+'数学-小节得分-2021'!B20*13.5%+'数学-小节得分-2022'!B20*14.5%+'数学-小节得分-2023'!B20*15.5%+'数学-小节得分-2024'!B20*16.5%+'数学-小节得分-2025'!B20*17.5%,1) -> 0.8 | C23: =COUNTA(F22:Y22) -> 2 | D23: =ROUND(B23/C23,2) -> 0.4 | E23: 掌握度（0~100） | F23: 0 | G23: 0
A24: 矩阵 | B24: 小节分数 | C24: 总节点数 | D24: 单节点分数 | E24: 节点 | F24: 矩阵的概念 | G24: 矩阵的线性运算 | H24: 矩阵的乘法 | I24: 方阵的幂 | J24: 方阵乘积的行列式 | K24: 矩阵的转置 | L24: 逆矩阵的概念和性质 | M24: 矩阵可逆的充分必要条件 | N24: 伴随矩阵 | O24: 矩阵的初等变换 | P24: 初等矩阵 | Q24: 矩阵的秩 | R24: 矩阵的等价 | S24: 分块矩阵及其运算
B25: =ROUND('数学-小节得分-2017'!B22*10%+'数学-小节得分-2020'!B22*12.5%+'数学-小节得分-2021'!B22*13.5%+'数学-小节得分-2022'!B22*14.5%+'数学-小节得分-2023'!B22*15.5%+'数学-小节得分-2024'!B22*16.5%+'数学-小节得分-2025'!B22*17.5%,1) -> 7.1 | C25: =COUNTA(F24:Y24) -> 14 | D25: =ROUND(B25/C25,2) -> 0.51 | E25: 掌握度（0~100） | F25: 0 | G25: 0 | H25: 0 | I25: 0 | J25: 0 | K25: 0 | L25: 0 | M25: 0 | N25: 0 | O25: 0 | P25: 0 | Q25: 0 | R25: 0 | S25: 0
A26: 向量 | B26: 小节分数 | C26: 总节点数 | D26: 单节点分数 | E26: 节点 | F26: 向量的概念 | G26: 向量的线性组合与线性表示 | H26: 向量组的线性相关与线性无关 | I26: 向量组的极大线性无关组 | J26: 等价向量组 | K26: 向量组的秩 | L26: 向量组的秩与矩阵的秩之间的关系 | M26: 向量空间及其相关概念 | N26: n维向量空间的基变换和坐标变换 | O26: 过渡矩阵 | P26: 向量的内积 | Q26: 线性无关向量组的正交规范化方法 | R26: 规范正交基 | S26: 正交矩阵及其性质
B27: =ROUND('数学-小节得分-2017'!B24*10%+'数学-小节得分-2020'!B24*12.5%+'数学-小节得分-2021'!B24*13.5%+'数学-小节得分-2022'!B24*14.5%+'数学-小节得分-2023'!B24*15.5%+'数学-小节得分-2024'!B24*16.5%+'数学-小节得分-2025'!B24*17.5%,1) -> 4.5 | C27: =COUNTA(F26:Y26) -> 14 | D27: =ROUND(B27/C27,2) -> 0.32 | E27: 掌握度（0~100） | F27: 0 | G27: 0 | H27: 0 | I27: 0 | J27: 0 | K27: 0 | L27: 0 | M27: 0 | N27: 0 | O27: 0 | P27: 0 | Q27: 0 | R27: 0 | S27: 0
A28: 线性方程组 | B28: 小节分数 | C28: 总节点数 | D28: 单节点分数 | E28: 节点 | F28: 线性方程组的克拉默（Cramer）法则 | G28: 齐次线性方程组有非零解的充分必要条件 | H28: 非齐次线性方程组有解的充分必要条件 | I28: 线性方程组解的性质和解的结构 | J28: 齐次线性方程组的基础解系和通解 | K28: 解空间 | L28: 非齐次线性方程组的通解
B29: =ROUND('数学-小节得分-2017'!B26*10%+'数学-小节得分-2020'!B26*12.5%+'数学-小节得分-2021'!B26*13.5%+'数学-小节得分-2022'!B26*14.5%+'数学-小节得分-2023'!B26*15.5%+'数学-小节得分-2024'!B26*16.5%+'数学-小节得分-2025'!B26*17.5%,1) -> 3.5 | C29: =COUNTA(F28:Y28) -> 7 | D29: =ROUND(B29/C29,2) -> 0.5 | E29: 掌握度（0~100） | F29: 0 | G29: 0 | H29: 0 | I29: 0 | J29: 0 | K29: 0 | L29: 0
A30: 矩阵的特征值和特征向量 | B30: 小节分数 | C30: 总节点数 | D30: 单节点分数 | E30: 节点 | F30: 矩阵的特征值和特征向量的概念、性质 | G30: 相似变换、相似矩阵的概念及性质 | H30: 矩阵可相似对角化的充分必要条件及相似对角矩阵 | I30: 实对称矩阵的特征值、特征向量及其相似对角矩阵
B31: =ROUND('数学-小节得分-2017'!B28*10%+'数学-小节得分-2020'!B28*12.5%+'数学-小节得分-2021'!B28*13.5%+'数学-小节得分-2022'!B28*14.5%+'数学-小节得分-2023'!B28*15.5%+'数学-小节得分-2024'!B28*16.5%+'数学-小节得分-2025'!B28*17.5%,1) -> 9.3 | C31: =COUNTA(F30:Y30) -> 4 | D31: =ROUND(B31/C31,2) -> 2.33 | E31: 掌握度（0~100） | F31: 0 | G31: 0 | H31: 0 | I31: 0
A32: 二次型 | B32: 小节分数 | C32: 总节点数 | D32: 单节点分数 | E32: 节点 | F32: 二次型及其矩阵表示 | G32: 合同变换与合同矩阵 | H32: 二次型的秩 | I32: 惯性定理 | J32: 二次型的标准形和规范形 | K32: 用正交变换和配方法化二次型为标准形 | L32: 二次型及其矩阵的正定性
B33: =ROUND('数学-小节得分-2017'!B30*10%+'数学-小节得分-2020'!B30*12.5%+'数学-小节得分-2021'!B30*13.5%+'数学-小节得分-2022'!B30*14.5%+'数学-小节得分-2023'!B30*15.5%+'数学-小节得分-2024'!B30*16.5%+'数学-小节得分-2025'!B30*17.5%,1) -> 6.4 | C33: =COUNTA(F32:Y32) -> 7 | D33: =ROUND(B33/C33,2) -> 0.91 | E33: 掌握度（0~100） | F33: 0 | G33: 0 | H33: 0 | I33: 0 | J33: 0 | K33: 0 | L33: 0
A34: 概率论（20%，30分）
A35: 总分 | B35: =SUM(F37:P37)*0.01*D37+SUM(F39:K39)*0.01*D39+SUM(F41:K41)*0.01*D41+SUM(F43:H43)*0.01*D43+SUM(F45:K45)*0.01*D45+SUM(F47:P47)*0.01*D47+SUM(F49:M49)*0.01*D49+SUM(F51:H51)*0.01*D51 -> 0
A36: 随机事件和概率 | B36: 小节分数 | C36: 总节点数 | D36: 单节点分数 | E36: 节点 | F36: 随机事件与样本空间 | G36: 事件的关系与运算 | H36: 完备事件组 | I36: 概率的概念 | J36: 概率的基本性质 | K36: 古典型概率 | L36: 几何型概率 | M36: 条件概率 | N36: 概率的基本公式 | O36: 事件的独立性 | P36: 独立重复试验
B37: =ROUND('数学-小节得分-2017'!B33*10%+'数学-小节得分-2020'!B33*12.5%+'数学-小节得分-2021'!B33*13.5%+'数学-小节得分-2022'!B33*14.5%+'数学-小节得分-2023'!B33*15.5%+'数学-小节得分-2024'!B33*16.5%+'数学-小节得分-2025'!B33*17.5%,1) -> 4.8 | C37: =COUNTA(F36:Y36) -> 11 | D37: =ROUND(B37/C37,2) -> 0.44 | E37: 掌握度（0~100） | F37: 0 | G37: 0 | H37: 0 | I37: 0 | J37: 0 | K37: 0 | L37: 0 | M37: 0 | N37: 0 | O37: 0 | P37: 0
A38: 随机变量及其分布 | B38: 小节分数 | C38: 总节点数 | D38: 单节点分数 | E38: 节点 | F38: 随机变量 | G38: 随机变量分布函数的概念及其性质 | H38: 离散型随机变量的概率分布 | I38: 连续型随机变量的概率密度 | J38: 常见随机变量的分布 | K38: 随机变量函数的分布
B39: =ROUND('数学-小节得分-2017'!B35*10%+'数学-小节得分-2020'!B35*12.5%+'数学-小节得分-2021'!B35*13.5%+'数学-小节得分-2022'!B35*14.5%+'数学-小节得分-2023'!B35*15.5%+'数学-小节得分-2024'!B35*16.5%+'数学-小节得分-2025'!B35*17.5%,1) -> 4.1 | C39: =COUNTA(F38:Y38) -> 6 | D39: =ROUND(B39/C39,2) -> 0.68 | E39: 掌握度（0~100） | F39: 0 | G39: 0 | H39: 0 | I39: 0 | J39: 0 | K39: 0
A40: 多维随机变量及其分布 | B40: 小节分数 | C40: 总节点数 | D40: 单节点分数 | E40: 节点 | F40: 多维随机变量及其分布 | G40: 二维离散型随机变量的概率分布、边缘分布和条件分布 | H40: 二维连续型随机变量的概率密度、边缘概率密度和条件密度 | I40: 随机变量的独立性和不相关性 | J40: 常用二维随机变量的分布 | K40: 两个及两个以上随机变量简单函数的分布
...

Sheet 408-分数面板
A1: 408考研面板总分 | B1: =SUM(B3,B19,B33,B45) -> 0
A2: 数据结构（30%，45分）
A3: 总分 | B3: =SUM(F5:G5)*D5/100+SUM(F7:I7)*D7/100+SUM(F9:K9)*D9/100+SUM(F11:P11)*D11/100+SUM(F13:O13)*D13/100+SUM(F15:P15)*D15/100+SUM(F17:Q17)*D17/100 -> 0
A4: 基本概念 | B4: 小节分数 | C4: 总节点数 | D4: 单节点分数 | E4: 节点 | F4: 数据结构的基本概念 | G4: 算法的基本概念
B5: =('408-小节得分-2017'!B3*$B$61+'408-小节得分-2018'!B3*$B$62+'408-小节得分-2019'!B3*$B$63+'408-小节得分-2020'!B3*$B$64+'408-小节得分-2021'!B3*$B$65+'408-小节得分-2022'!B3*$B$66+'408-小节得分-2023'!B3*$B$67+'408-小节得分-2024'!B3*$B$68+'408-小节得分-2025'!B3*$B$69)/SUM($B$61:$B$69) -> 2.315 | C5: =COUNTA(F4:G4) -> 2 | D5: =B5/C5 -> 1.1575 | E5: 掌握度（0~100） | F5: 0 | G5: 0
A6: 线性表 | B6: 小节分数 | C6: 总节点数 | D6: 单节点分数 | E6: 节点 | F6: 线性表的基本概念 | G6: 线性表的实现：顺序存储 | H6: 线性表的实现：链式存储 | I6: 线性表的应用
B7: =('408-小节得分-2017'!B5*$B$61+'408-小节得分-2018'!B5*$B$62+'408-小节得分-2019'!B5*$B$63+'408-小节得分-2020'!B5*$B$64+'408-小节得分-2021'!B5*$B$65+'408-小节得分-2022'!B5*$B$66+'408-小节得分-2023'!B5*$B$67+'408-小节得分-2024'!B5*$B$68+'408-小节得分-2025'!B5*$B$69)/SUM($B$61:$B$69) -> 5.88 | C7: =COUNTA(F6:I6) -> 4 | D7: =B7/C7 -> 1.47 | E7: 掌握度（0~100） | F7: 0 | G7: 0 | H7: 0 | I7: 0
A8: 栈、队列和数组 | B8: 小节分数 | C8: 总节点数 | D8: 单节点分数 | E8: 节点 | F8: 栈和队列的基本概念 | G8: 栈和队列的顺序存储结构 | H8: 栈和队列的链式存储结构 | I8: 多维数组的存储 | J8: 特殊矩阵的压缩存储 | K8: 栈、队列和数组的应用
B9: =('408-小节得分-2017'!B7*$B$61+'408-小节得分-2018'!B7*$B$62+'408-小节得分-2019'!B7*$B$63+'408-小节得分-2020'!B7*$B$64+'408-小节得分-2021'!B7*$B$65+'408-小节得分-2022'!B7*$B$66+'408-小节得分-2023'!B7*$B$67+'408-小节得分-2024'!B7*$B$68+'408-小节得分-2025'!B7*$B$69)/SUM($B$61:$B$69) -> 3.79 | C9: =COUNTA(F8:K8) -> 6 | D9: =B9/C9 -> 0.63166667 | E9: 掌握度（0~100） | F9: 0 | G9: 0 | H9: 0 | I9: 0 | J9: 0 | K9: 0
A10: 树和二叉树 | B10: 小节分数 | C10: 总节点数 | D10: 单节点分数 | E10: 节点 | F10: 树的基本概念 | G10: 二叉树的定义及其主要特性 | H10: 二叉树的顺序存储结构和链式存储结构 | I10: 二叉树的遍历 | J10: 线索二叉树的基本概念和构造 | K10: 树的存储结构 | L10: 森林与二叉树的转换 | M10: 树和森林的遍历 | N10: 哈夫曼（Huffman）树和哈夫曼编码 | O10: 并查集及其应用 | P10: 堆及其应用
B11: =('408-小节得分-2017'!B9*$B$61+'408-小节得分-2018'!B9*$B$62+'408-小节得分-2019'!B9*$B$63+'408-小节得分-2020'!B9*$B$64+'408-小节得分-2021'!B9*$B$65+'408-小节得分-2022'!B9*$B$66+'408-小节得分-2023'!B9*$B$67+'408-小节得分-2024'!B9*$B$68+'408-小节得分-2025'!B9*$B$69)/SUM($B$61:$B$69) -> 9.2525 | C11: =COUNTA(F10:P10) -> 11 | D11: =B11/C11 -> 0.84113636 | E11: 掌握度（0~100） | F11: 0 | G11: 0 | H11: 0 | I11: 0 | J11: 0 | K11: 0 | L11: 0 | M11: 0 | N11: 0 | O11: 0 | P11: 0
A12: 图 | B12: 小节分数 | C12: 总节点数 | D12: 单节点分数 | E12: 节点 | F12: 图的基本概念 | G12: 图的存储及基本操作：邻接矩阵 | H12: 图的存储及基本操作：邻接表 | I12: 图的存储及基本操作：邻接多重表、十字链表 | J12: 图的遍历：深度优先搜索 | K12: 图的遍历：广度优先搜索 | L12: 最小（代价）生成树 | M12: 最短路径 | N12: 拓扑排序 | O12: 关键路径
B13: =('408-小节得分-2017'!B11*$B$61+'408-小节得分-2018'!B11*$B$62+'408-小节得分-2019'!B11*$B$63+'408-小节得分-2020'!B11*$B$64+'408-小节得分-2021'!B11*$B$65+'408-小节得分-2022'!B11*$B$66+'408-小节得分-2023'!B11*$B$67+'408-小节得分-2024'!B11*$B$68+'408-小节得分-2025'!B11*$B$69)/SUM($B$61:$B$69) -> 10.77 | C13: =COUNTA(F12:O12) -> 10 | D13: =B13/C13 -> 1.077 | E13: 掌握度（0~100） | F13: 0 | G13: 0 | H13: 0 | I13: 0 | J13: 0 | K13: 0 | L13: 0 | M13: 0 | N13: 0 | O13: 0
A14: 查找 | B14: 小节分数 | C14: 总节点数 | D14: 单节点分数 | E14: 节点 | F14: 查找的基本概念 | G14: 顺序查找法 | H14: 分块查找法 | I14: 折半查找法 | J14: 二叉搜索树 | K14: 平衡二叉树 | L14: 红黑树 | M14: B树及其基本操作、B+树的基本概念 | N14: 散列（Hash）表 | O14: 字符串模式匹配 | P14: 查找算法的分析及应用
B15: =('408-小节得分-2017'!B13*$B$61+'408-小节得分-2018'!B13*$B$62+'408-小节得分-2019'!B13*$B$63+'408-小节得分-2020'!B13*$B$64+'408-小节得分-2021'!B13*$B$65+'408-小节得分-2022'!B13*$B$66+'408-小节得分-2023'!B13*$B$67+'408-小节得分-2024'!B13*$B$68+'408-小节得分-2025'!B13*$B$69)/SUM($B$61:$B$69) -> 7.2075 | C15: =COUNTA(F14:P14) -> 11 | D15: =B15/C15 -> 0.65522727 | E15: 掌握度（0~100） | F15: 0 | G15: 0 | H15: 0 | I15: 0 | J15: 0 | K15: 0 | L15: 0 | M15: 0 | N15: 0 | O15: 0 | P15: 0
A16: 排序 | B16: 小节分数 | C16: 总节点数 | D16: 单节点分数 | E16: 节点 | F16: 排序的基本概念 | G16: 直接插入排序 | H16: 折半插入排序 | I16: 起泡排序（Bubble Sort） | J16: 简单选择排序 | K16: 希尔排序（Shell Sort） | L16: 快速排序 | M16: 堆排序 | N16: 二路归并排序（Merge Sort） | O16: 基数排序 | P16: 外部排序 | Q16: 排序算法的分析与应用
B17: =('408-小节得分-2017'!B15*$B$61+'408-小节得分-2018'!B15*$B$62+'408-小节得分-2019'!B15*$B$63+'408-小节得分-2020'!B15*$B$64+'408-小节得分-2021'!B15*$B$65+'408-小节得分-2022'!B15*$B$66+'408-小节得分-2023'!B15*$B$67+'408-小节得分-2024'!B15*$B$68+'408-小节得分-2025'!B15*$B$69)/SUM($B$61:$B$69) -> 5.92 | C17: =COUNTA(F16:Q16) -> 12 | D17: =B17/C17 -> 0.49333333 | E17: 掌握度（0~100） | F17: 0 | G17: 0 | H17: 0 | I17: 0 | J17: 0 | K17: 0 | L17: 0 | M17: 0 | N17: 0 | O17: 0 | P17: 0 | Q17: 0
A18: 计算机组成原理（30%，45分）
A19: 总分 | B19: =SUM(F21:J21)*D21/100+SUM(F23:N23)*D23/100+SUM(F25:W25)*D25/100+SUM(F27:N27)*D27/100+SUM(F29:T29)*D29/100+SUM(F31:M31)*D31/100 -> 0
A20: 计算机系统概述 | B20: 小节分数 | C20: 总节点数 | D20: 单节点分数 | E20: 节点 | F20: 计算机系统的基本组成 | G20: 计算机硬件的基本组成 | H20: 计算机软件和硬件的关系 | I20: 计算机系统的工作原理：“存储程序”工作方式，高级语言程序与机器语言程序之间的转换，程序和指令的执行过程 | J20: 计算机性能指标：吞吐量、响应时间；CPU时钟周期、主频、CPI、CPU执行时间；MIPS、MFLOPS、GFLOPS、TFLOPS、PFLOPS、EFLOPS、ZFLOPS
B21: =('408-小节得分-2017'!B18*$B$61+'408-小节得分-2018'!B18*$B$62+'408-小节得分-2019'!B18*$B$63+'408-小节得分-2020'!B18*$B$64+'408-小节得分-2021'!B18*$B$65+'408-小节得分-2022'!B18*$B$66+'408-小节得分-2023'!B18*$B$67+'408-小节得分-2024'!B18*$B$68+'408-小节得分-2025'!B18*$B$69)/SUM($B$61:$B$69) -> 1.53 | C21: =COUNTA(F20:J20) -> 5 | D21: =B21/C21 -> 0.306 | E21: 掌握度（0~100） | F21: 0 | G21: 0 | H21: 0 | I21: 0 | J21: 0
A22: 数据的表示和运算 | B22: 小节分数 | C22: 总节点数 | D22: 单节点分数 | E22: 节点 | F22: 进位计数制及其数据之间的相互转换 | G22: 定点数的编码表示 | H22: 基本运算部件：加法器，算术逻辑部件（ALU） | I22: 加/减运算：补码加/减运算器，标志位的生成 | J22: 乘/除运算：乘/除法运算的基本原理，乘法电路和除法电路的基本结构 | K22: 无符号整数的表示和运算 | L22: 带符号整数的表示和运算 | M22: 浮点数的表示：IEEE754标准 | N22: 浮点数的加/减运算
B23: =('408-小节得分-2017'!B20*$B$61+'408-小节得分-2018'!B20*$B$62+'408-小节得分-2019'!B20*$B$63+'408-小节得分-2020'!B20*$B$64+'408-小节得分-2021'!B20*$B$65+'408-小节得分-2022'!B20*$B$66+'408-小节得分-2023'!B20*$B$67+'408-小节得分-2024'!B20*$B$68+'408-小节得分-2025'!B20*$B$69)/SUM($B$61:$B$69) -> 10.2525 | C23: =COUNTA(F22:N22) -> 9 | D23: =B23/C23 -> 1.1391667 | E23: 掌握度（0~100） | F23: 0 | G23: 0 | H23: 0 | I23: 0 | J23: 0 | K23: 0 | L23: 0 | M23: 0 | N23: 0
A24: 存储器层次结构 | B24: 小节分数 | C24: 总节点数 | D24: 单节点分数 | E24: 节点 | F24: 存储器的分类 | G24: 层次化存储器的基本结构 | H24: SRAM存储器 | I24: DRAM存储器 | J24: Flash存储器 | K24: DRAM芯片和内存条 | L24: 多模块存储器 | M24: 主存和CPU之间的连接 | N24: 磁盘存储器 | O24: 固态硬盘（SSD） | P24: Cache的基本原理 | Q24: Cache和主存之间的映射方式 | R24: Cache中主存块的替换算法 | S24: Cache写策略 | T24: 虚拟存储器的基本概念 | U24: 页式虚拟存储器：基本原理，页表，地址转换，TLB（快表） | V24: 段式虚拟存储器的基本原理 | W24: 段页式虚拟存储器的基本原理
B25: =('408-小节得分-2017'!B22*$B$61+'408-小节得分-2018'!B22*$B$62+'408-小节得分-2019'!B22*$B$63+'408-小节得分-2020'!B22*$B$64+'408-小节得分-2021'!B22*$B$65+'408-小节得分-2022'!B22*$B$66+'408-小节得分-2023'!B22*$B$67+'408-小节得分-2024'!B22*$B$68+'408-小节得分-2025'!B22*$B$69)/SUM($B$61:$B$69) -> 11.88 | C25: =COUNTA(F24:W24) -> 18 | D25: =B25/C25 -> 0.66 | E25: 掌握度（0~100） | F25: 0 | G25: 0 | H25: 0 | I25: 0 | J25: 0 | K25: 0 | L25: 0 | M25: 0 | N25: 0 | O25: 0 | P25: 0 | Q25: 0 | R25: 0 | S25: 0 | T25: 0 | U25: 0 | V25: 0 | W25: 0
A26: 指令系统 | B26: 小节分数 | C26: 总节点数 | D26: 单节点分数 | E26: 节点 | F26: 指令系统的基本概念 | G26: 指令格式 | H26: 寻址方式 | I26: 数据的对齐和大小端存放方式 | J26: CISC和RISC的基本概念 | K26: 编译器、汇编器和链接器的基本概念 | L26: 选择结构语句的机器级表示 | M26: 循环结构语句的机器级表示 | N26: 过程（函数）调用对应的机器级表示
B27: =('408-小节得分-2017'!B24*$B$61+'408-小节得分-2018'!B24*$B$62+'408-小节得分-2019'!B24*$B$63+'408-小节得分-2020'!B24*$B$64+'408-小节得分-2021'!B24*$B$65+'408-小节得分-2022'!B24*$B$66+'408-小节得分-2023'!B24*$B$67+'408-小节得分-2024'!B24*$B$68+'408-小节得分-2025'!B24*$B$69)/SUM($B$61:$B$69) -> 7.6 | C27: =COUNTA(F26:N26) -> 9 | D27: =B27/C27 -> 0.84444444 | E27: 掌握度（0~100） | F27: 0 | G27: 0 | H27: 0 | I27: 0 | J27: 0 | K27: 0 | L27: 0 | M27: 0 | N27: 0
A28: 中央处理器（CPU） | B28: 小节分数 | C28: 总节点数 | D28: 单节点分数 | E28: 节点 | F28: CPU的功能和基本结构 | G28: 指令执行过程 | H28: 数据通路的功能和基本结构 | I28: 控制器的功能和工作原理 | J28: 异常和中断的基本概念 | K28: 异常和中断的分类 | L28: 异常和中断的检测与响应 | M28: 指令流水线的基本概念 | N28: 指令流水线的基本实现 | O28: 结构冒险、数据冒险和控制冒险的处理 | P28: 超标量和动态流水线的基本概念 | Q28: SISD、SIMD、MIMD、向量处理器的基本概念 | R28: 硬件多线程的基本概念 | S28: 多核（multi-core）处理器的基本概念 | T28: 共享内存多处理器（SMP）的基本概念
B29: =('408-小节得分-2017'!B26*$B$61+'408-小节得分-2018'!B26*$B$62+'408-小节得分-2019'!B26*$B$63+'408-小节得分-2020'!B26*$B$64+'408-小节得分-2021'!B26*$B$65+'408-小节得分-2022'!B26*$B$66+'408-小节得分-2023'!B26*$B$67+'408-小节得分-2024'!B26*$B$68+'408-小节得分-2025'!B26*$B$69)/SUM($B$61:$B$69) -> 7.7925 | C29: =COUNTA(F28:T28) -> 15 | D29: =B29/C29 -> 0.5195 | E29: 掌握度（0~100） | F29: 0 | G29: 0 | H29: 0 | I29: 0 | J29: 0 | K29: 0 | L29: 0 | M29: 0 | N29: 0 | O29: 0 | P29: 0 | Q29: 0 | R29: 0 | S29: 0 | T29: 0
A30: 总线和输入输出系统 | B30: 小节分数 | C30: 总节点数 | D30: 单节点分数 | E30: 节点 | F30: 总线的基本概念 | G30: 总线的组成及性能指标 | H30: 总线事务和定时 | I30: I/O接口的功能和基本结构 | J30: I/O端口及其编址 | K30: 程序查询方式 | L30: 程序中断方式：中断的基本概念，中断响应过程，中断处理过程，多重中断和中断屏蔽的概念 | M30: DMA方式：DMA控制器的组成，DMA传送过程
B31: =('408-小节得分-2017'!B28*$B$61+'408-小节得分-2018'!B28*$B$62+'408-小节得分-2019'!B28*$B$63+'408-小节得分-2020'!B28*$B$64+'408-小节得分-2021'!B28*$B$65+'408-小节得分-2022'!B28*$B$66+'408-小节得分-2023'!B28*$B$67+'408-小节得分-2024'!B28*$B$68+'408-小节得分-2025'!B28*$B$69)/SUM($B$61:$B$69) -> 5.945 | C31: =COUNTA(F30:M30) -> 8 | D31: =B31/C31 -> 0.743125 | E31: 掌握度（0~100） | F31: 0 | G31: 0 | H31: 0 | I31: 0 | J31: 0 | K31: 0 | L31: 0 | M31: 0
A32: 操作系统（23.33%，35分）
A33: 总分 | B33: =SUM(F35:O35)*D35/100+SUM(F37:Z37)*D37/100+SUM(F39:P39)*D39/100+SUM(F41:S41)*D41/100+SUM(F43:O43)*D43/100 -> 0
A34: 操作系统基础 | B34: 小节分数 | C34: 总节点数 | D34: 单节点分数 | E34: 节点 | F34: 操作系统的基本概念 | G34: 操作系统发展历程 | H34: CPU运行模式：内核模式，用户模式 | I34: 中断和异常的处理 | J34: 系统调用 | K34: 程序的链接与装入 | L34: 程序运行时内存映像与地址空间 | M34: 操作系统结构：分层，模块化，宏内核，微内核，外核 | N34: 操作系统引导 | O34: 虚拟机
B35: =('408-小节得分-2017'!B31*$B$61+'408-小节得分-2018'!B31*$B$62+'408-小节得分-2019'!B31*$B$63+'408-小节得分-2020'!B31*$B$64+'408-小节得分-2021'!B31*$B$65+'408-小节得分-2022'!B31*$B$66+'408-小节得分-2023'!B31*$B$67+'408-小节得分-2024'!B31*$B$68+'408-小节得分-2025'!B31*$B$69)/SUM($B$61:$B$69) -> 5.1025 | C35: =COUNTA(F34:O34) -> 10 | D35: =B35/C35 -> 0.51025 | E35: 掌握度（0~100） | F35: 0 | G35: 0 | H35: 0 | I35: 0 | J35: 0 | K35: 0 | L35: 0 | M35: 0 | N35: 0 | O35: 0
A36: 进程管理 | B36: 小节分数 | C36: 总节点数 | D36: 单节点分数 | E36: 节点 | F36: 进程与线程的基本概念 | G36: 进程/线程的状态与转换 | H36: 线程的实现：内核支持的线程，线程库支持的线程 | I36: 进程与线程的组织与控制 | J36: 进程间通信：共享内存，消息传递，管道，信号 | K36: CPU调度的基本概念 | L36: CPU调度的目标 | M36: CPU调度的实现：调度器/调度程序（scheduler），调度的时机与调度方式（抢占式/非抢占式），闲逛进程，内核级线程与用户级线程调度 | N36: CPU调度算法 | O36: 多处理机调度 | P36: 上下文及其切换机制 | Q36: 同步与互斥的基本概念 | R36: 同步与互斥的基本实现方法：软件方法，硬件方法 | S36: 锁 | T36: 信号量 | U36: 条件变量 | V36: 经典同步问题：生产者-消费者问题，读者-写者问题，哲学家进餐问题等 | W36: 死锁的基本概念 | X36: 死锁预防 | Y36: 死锁避免 | Z36: 死锁检测和解除
B37: =('408-小节得分-2017'!B33*$B$61+'408-小节得分-2018'!B33*$B$62+'408-小节得分-2019'!B33*$B$63+'408-小节得分-2020'!B33*$B$64+'408-小节得分-2021'!B33*$B$65+'408-小节得分-2022'!B33*$B$66+'408-小节得分-2023'!B33*$B$67+'408-小节得分-2024'!B33*$B$68+'408-小节得分-2025'!B33*$B$69)/SUM($B$61:$B$69) -> 14.39 | C37: =COUNTA(F36:Z36) -> 21 | D37: =B37/C37 -> 0.6852381 | E37: 掌握度（0~100） | F37: 0 | G37: 0 | H37: 0 | I37: 0 | J37: 0 | K37: 0 | L37: 0 | M37: 0 | N37: 0 | O37: 0 | P37: 0 | Q37: 0 | R37: 0 | S37: 0 | T37: 0 | U37: 0 | V37: 0 | W37: 0 | X37: 0 | Y37: 0 | Z37: 0
A38: 内存管理 | B38: 小节分数 | C38: 总节点数 | D38: 单节点分数 | E38: 节点 | F38: 内存管理的基本概念：逻辑地址空间与物理地址空间，地址变换，内存共享，内存保护，内存分配与回收 | G38: 连续分配管理方式 | H38: 页式管理 | I38: 段式管理 | J38: 段页式管理 | K38: 虚拟内存的基本概念 | L38: 请求页式管理 | M38: 页框分配与回收 | N38: 页置换算法 | O38: 内存映射文件（Memory-Mapped Files） | P38: 虚拟存储器性能的影响因素及改进方法
B39: =('408-小节得分-2017'!B35*$B$61+'408-小节得分-2018'!B35*$B$62+'408-小节得分-2019'!B35*$B$63+'408-小节得分-2020'!B35*$B$64+'408-小节得分-2021'!B35*$B$65+'408-小节得分-2022'!B35*$B$66+'408-小节得分-2023'!B35*$B$67+'408-小节得分-2024'!B35*$B$68+'408-小节得分-2025'!B35*$B$69)/SUM($B$61:$B$69) -> 6.56 | C39: =COUNTA(F38:P38) -> 11 | D39: =B39/C39 -> 0.59636364 | E39: 掌握度（0~100） | F39: 0 | G39: 0 | H39: 0 | I39: 0 | J39: 0 | K39: 0 | L39: 0 | M39: 0 | N39: 0 | O39: 0 | P39: 0
A40: 文件管理 | B40: 小节分数 | C40: 总节点数 | D40: 单节点分数 | E40: 节点 | F40: 文件的基本概念 | G40: 文件元数据和索引节点（inode） | H40: 文件的操作：建立，删除，打开，关闭，读，写 | I40: 文件的保护 | J40: 文件的逻辑结构 | K40: 文件的物理结构 | L40: 目录的基本概念 | M40: 树形目录 | N40: 目录的操作 | O40: 硬链接和软链接 | P40: 文件系统的全局结构（layout）：文件系统在外存中的结构，文件系统在内存中的结构 | Q40: 外存空闲空间管理方法 | R40: 虚拟文件系统 | S40: 文件系统挂载（mounting）
...

Sheet 数学-小节得分-2025
A1: 高等数学（60%，90分）
A2: 函数，极限，连续 | B2: 小节得分
B3: 7.5
A4: 一元函数微分 | B4: 小节得分
B5: 17
A6: 一元函数积分 | B6: 小节得分
B7: 12.5
A8: 向量代数与空间解析几何 | B8: 小节得分
B9: 7
A10: 多元函数微分 | B10: 小节得分
B11: 11
A12: 多元函数积分 | B12: 小节得分
B13: 17
A14: 无穷级数 | B14: 小节得分
B15: 10
A16: 常微分方程 | B16: 小节得分
B17: 6
A18: 线性代数（20%，30分）
A19: 行列式 | B19: 小节得分
B20: 0
A21: 矩阵 | B21: 小节得分
B22: 7.5
A23: 向量 | B23: 小节得分
B24: 2.5
A25: 线性方程组 | B25: 小节得分
B26: 8.5
A27: 矩阵的特征值和特征向量 | B27: 小节得分
B28: 7.5
A29: 二次型 | B29: 小节得分
B30: 5
A31: 概率论（20%，30分）
A32: 随机事件和概率 | B32: 小节得分
B33: 8
A34: 随机变量及其分布 | B34: 小节得分
B35: 7.5
A36: 多维随机变量及其分布 | B36: 小节得分
B37: 3
A38: 随机变量的数字特征 | B38: 小节得分
B39: 7.5
A40: 大数定律和中心极限定理 | B40: 小节得分
...

Sheet 数学-小节得分-2024
A1: 高等数学（60%，90分）
A2: 函数，极限，连续 | B2: 小节得分
B3: 12.5
A4: 一元函数微分 | B4: 小节得分
B5: 12.5
A6: 一元函数积分 | B6: 小节得分
B7: 4.5
A8: 向量代数与空间解析几何 | B8: 小节得分
B9: 6
A10: 多元函数微分 | B10: 小节得分
B11: 17
A12: 多元函数积分 | B12: 小节得分
B13: 23
A14: 无穷级数 | B14: 小节得分
B15: 7.5
A16: 常微分方程 | B16: 小节得分
B17: 5
A18: 线性代数（20%，30分）
A19: 行列式 | B19: 小节得分
B20: 0
A21: 矩阵 | B21: 小节得分
B22: 8
A23: 向量 | B23: 小节得分
B24: 5
A25: 线性方程组 | B25: 小节得分
B26: 2.5
A27: 矩阵的特征值和特征向量 | B27: 小节得分
B28: 10.5
A29: 二次型 | B29: 小节得分
B30: 5
A31: 概率论（20%，30分）
A32: 随机事件和概率 | B32: 小节得分
B33: 5
A34: 随机变量及其分布 | B34: 小节得分
B35: 2.5
A36: 多维随机变量及其分布 | B36: 小节得分
B37: 10
A38: 随机变量的数字特征 | B38: 小节得分
B39: 5
A40: 大数定律和中心极限定理 | B40: 小节得分
...

Sheet 数学-小节得分-2023
A1: 高等数学（60%，90分）
A2: 函数，极限，连续 | B2: 小节得分
B3: 7.5
A4: 一元函数微分 | B4: 小节得分
B5: 25.5
A6: 一元函数积分 | B6: 小节得分
B7: 8.5
A8: 向量代数与空间解析几何 | B8: 小节得分
B9: 0
A10: 多元函数微分 | B10: 小节得分
B11: 17
A12: 多元函数积分 | B12: 小节得分
B13: 12
A14: 无穷级数 | B14: 小节得分
B15: 10
A16: 常微分方程 | B16: 小节得分
B17: 7.5
A18: 线性代数（20%，30分）
A19: 行列式 | B19: 小节得分
B20: 0
A21: 矩阵 | B21: 小节得分
B22: 5
A23: 向量 | B23: 小节得分
B24: 7.5
A25: 线性方程组 | B25: 小节得分
B26: 2.5
A27: 矩阵的特征值和特征向量 | B27: 小节得分
B28: 7
A29: 二次型 | B29: 小节得分
B30: 9
A31: 概率论（20%，30分）
A32: 随机事件和概率 | B32: 小节得分
B33: 0
A34: 随机变量及其分布 | B34: 小节得分
B35: 2.5
A36: 多维随机变量及其分布 | B36: 小节得分
B37: 11.5
A38: 随机变量的数字特征 | B38: 小节得分
B39: 9.5
A40: 大数定律和中心极限定理 | B40: 小节得分
...

Sheet 数学-小节得分-2022
A1: 高等数学（60%，90分）
A2: 函数，极限，连续 | B2: 小节得分
B3: 10
A4: 一元函数微分 | B4: 小节得分
B5: 12
A6: 一元函数积分 | B6: 小节得分
B7: 16
A8: 向量代数与空间解析几何 | B8: 小节得分
B9: 0
A10: 多元函数微分 | B10: 小节得分
B11: 15
A12: 多元函数积分 | B12: 小节得分
B13: 24
A14: 无穷级数 | B14: 小节得分
B15: 5
A16: 常微分方程 | B16: 小节得分
B17: 6
A18: 线性代数（20%，30分）
A19: 行列式 | B19: 小节得分
B20: 0
A21: 矩阵 | B21: 小节得分
B22: 7.5
A23: 向量 | B23: 小节得分
B24: 5
A25: 线性方程组 | B25: 小节得分
B26: 4
A27: 矩阵的特征值和特征向量 | B27: 小节得分
B28: 8
A29: 二次型 | B29: 小节得分
B30: 6.5
A31: 概率论（20%，30分）
A32: 随机事件和概率 | B32: 小节得分
B33: 5
A34: 随机变量及其分布 | B34: 小节得分
B35: 0
A36: 多维随机变量及其分布 | B36: 小节得分
B37: 2.5
A38: 随机变量的数字特征 | B38: 小节得分
B39: 15.5
A40: 大数定律和中心极限定理 | B40: 小节得分
...

Sheet 数学-小节得分-2021
A1: 高等数学（60%，90分）
A2: 函数，极限，连续 | B2: 小节得分
B3: 7.5
A4: 一元函数微分 | B4: 小节得分
B5: 17.5
A6: 一元函数积分 | B6: 小节得分
B7: 10
A8: 向量代数与空间解析几何 | B8: 小节得分
B9: 6
A10: 多元函数微分 | B10: 小节得分
B11: 11
A12: 多元函数积分 | B12: 小节得分
B13: 17
A14: 无穷级数 | B14: 小节得分
B15: 12
A16: 常微分方程 | B16: 小节得分
B17: 5
A18: 线性代数（20%，30分）
A19: 行列式 | B19: 小节得分
B20: 2.5
A21: 矩阵 | B21: 小节得分
B22: 7.5
A23: 向量 | B23: 小节得分
B24: 5
A25: 线性方程组 | B25: 小节得分
B26: 0
A27: 矩阵的特征值和特征向量 | B27: 小节得分
B28: 9
A29: 二次型 | B29: 小节得分
B30: 8
A31: 概率论（20%，30分）
A32: 随机事件和概率 | B32: 小节得分
B33: 5
A34: 随机变量及其分布 | B34: 小节得分
B35: 8
A36: 多维随机变量及其分布 | B36: 小节得分
B37: 2.5
A38: 随机变量的数字特征 | B38: 小节得分
B39: 9
A40: 大数定律和中心极限定理 | B40: 小节得分
...

Sheet 数学-小节得分-2020
A1: 高等数学（60%，90分）
A2: 函数，极限，连续 | B2: 小节得分
B3: 8
A4: 一元函数微分 | B4: 小节得分
B5: 16
A6: 一元函数积分 | B6: 小节得分
B7: 6
A8: 向量代数与空间解析几何 | B8: 小节得分
B9: 4
A10: 多元函数微分 | B10: 小节得分
B11: 14
A12: 多元函数积分 | B12: 小节得分
B13: 20
A14: 无穷级数 | B14: 小节得分
B15: 9
A16: 常微分方程 | B16: 小节得分
B17: 7
A18: 线性代数（20%，30分）
A19: 行列式 | B19: 小节得分
B20: 4
A21: 矩阵 | B21: 小节得分
B22: 6
A23: 向量 | B23: 小节得分
B24: 4
A25: 线性方程组 | B25: 小节得分
B26: 0
A27: 矩阵的特征值和特征向量 | B27: 小节得分
B28: 12.5
A29: 二次型 | B29: 小节得分
B30: 5.5
A31: 概率论（20%，30分）
A32: 随机事件和概率 | B32: 小节得分
B33: 6
A34: 随机变量及其分布 | B34: 小节得分
B35: 2
A36: 多维随机变量及其分布 | B36: 小节得分
B37: 11
A38: 随机变量的数字特征 | B38: 小节得分
B39: 4
A40: 大数定律和中心极限定理 | B40: 小节得分
...

Sheet 数学-小节得分-2019
A1: 高等数学（60%，90分）
A2: 函数，极限，连续 | B2: 小节得分
A4: 一元函数微分 | B4: 小节得分
A6: 一元函数积分 | B6: 小节得分
A8: 向量代数与空间解析几何 | B8: 小节得分
A10: 多元函数微分 | B10: 小节得分
A12: 多元函数积分 | B12: 小节得分
A14: 无穷级数 | B14: 小节得分
A16: 常微分方程 | B16: 小节得分
A18: 线性代数（20%，30分）
A19: 行列式 | B19: 小节得分
A21: 矩阵 | B21: 小节得分
A23: 向量 | B23: 小节得分
A25: 线性方程组 | B25: 小节得分
A27: 矩阵的特征值和特征向量 | B27: 小节得分
A29: 二次型 | B29: 小节得分
A31: 概率论（20%，30分）
A32: 随机事件和概率 | B32: 小节得分
A34: 随机变量及其分布 | B34: 小节得分
A36: 多维随机变量及其分布 | B36: 小节得分
A38: 随机变量的数字特征 | B38: 小节得分
A40: 大数定律和中心极限定理 | B40: 小节得分
A42: 数理统计的基本概念 | B42: 小节得分
A44: 参数估计 | B44: 小节得分
A46: 假设检验 | B46: 小节得分

Sheet 数学-小节得分-2018
A1: 高等数学（60%，90分）
A2: 函数，极限，连续 | B2: 小节得分
A4: 一元函数微分 | B4: 小节得分
A6: 一元函数积分 | B6: 小节得分
A8: 向量代数与空间解析几何 | B8: 小节得分
A10: 多元函数微分 | B10: 小节得分
A12: 多元函数积分 | B12: 小节得分
A14: 无穷级数 | B14: 小节得分
A16: 常微分方程 | B16: 小节得分
A18: 线性代数（20%，30分）
A19: 行列式 | B19: 小节得分
A21: 矩阵 | B21: 小节得分
A23: 向量 | B23: 小节得分
A25: 线性方程组 | B25: 小节得分
A27: 矩阵的特征值和特征向量 | B27: 小节得分
A29: 二次型 | B29: 小节得分
A31: 概率论（20%，30分）
A32: 随机事件和概率 | B32: 小节得分
A34: 随机变量及其分布 | B34: 小节得分
A36: 多维随机变量及其分布 | B36: 小节得分
A38: 随机变量的数字特征 | B38: 小节得分
A40: 大数定律和中心极限定理 | B40: 小节得分
A42: 数理统计的基本概念 | B42: 小节得分
A44: 参数估计 | B44: 小节得分
A46: 假设检验 | B46: 小节得分

Sheet 数学-小节得分-2017
A1: 高等数学（60%，90分）
A2: 函数，极限，连续 | B2: 小节得分
B3: 12
A4: 一元函数微分 | B4: 小节得分
B5: 25
A6: 一元函数积分 | B6: 小节得分
B7: 9
A8: 向量代数与空间解析几何 | B8: 小节得分
B9: 3
A10: 多元函数微分 | B10: 小节得分
B11: 14
A12: 多元函数积分 | B12: 小节得分
B13: 11
A14: 无穷级数 | B14: 小节得分
B15: 4
A16: 常微分方程 | B16: 小节得分
B17: 4
A18: 线性代数（20%，30分）
A19: 行列式 | B19: 小节得分
B20: 0
A21: 矩阵 | B21: 小节得分
B22: 8.5
A23: 向量 | B23: 小节得分
B24: 2
A25: 线性方程组 | B25: 小节得分
B26: 6
A27: 矩阵的特征值和特征向量 | B27: 小节得分
B28: 12
A29: 二次型 | B29: 小节得分
B30: 5.5
A31: 概率论（20%，30分）
A32: 随机事件和概率 | B32: 小节得分
B33: 4
A34: 随机变量及其分布 | B34: 小节得分
B35: 7
A36: 多维随机变量及其分布 | B36: 小节得分
B37: 7
A38: 随机变量的数字特征 | B38: 小节得分
B39: 4
A40: 大数定律和中心极限定理 | B40: 小节得分
...

Sheet 数学-小节得分-2016
A1: 高等数学（60%，90分）
A2: 函数，极限，连续 | B2: 小节得分
A4: 一元函数微分 | B4: 小节得分
A6: 一元函数积分 | B6: 小节得分
A8: 向量代数与空间解析几何 | B8: 小节得分
A10: 多元函数微分 | B10: 小节得分
A12: 多元函数积分 | B12: 小节得分
A14: 无穷级数 | B14: 小节得分
A16: 常微分方程 | B16: 小节得分
A18: 线性代数（20%，30分）
A19: 行列式 | B19: 小节得分
A21: 矩阵 | B21: 小节得分
A23: 向量 | B23: 小节得分
A25: 线性方程组 | B25: 小节得分
A27: 矩阵的特征值和特征向量 | B27: 小节得分
A29: 二次型 | B29: 小节得分
A31: 概率论（20%，30分）
A32: 随机事件和概率 | B32: 小节得分
A34: 随机变量及其分布 | B34: 小节得分
A36: 多维随机变量及其分布 | B36: 小节得分
A38: 随机变量的数字特征 | B38: 小节得分
A40: 大数定律和中心极限定理 | B40: 小节得分
A42: 数理统计的基本概念 | B42: 小节得分
A44: 参数估计 | B44: 小节得分
A46: 假设检验 | B46: 小节得分

Sheet 数学-考点分布-2017
A1: 题号 | B1: 考点（即：小节） | C1: 分数
A2: 1 | B2: 函数，极限，连续 | C2: 4
A3: 2 | B3: 一元函数微分 | C3: 4
A4: 3 | B4: 多元函数微分 | C4: 4
A5: 4 | B5: 一元函数积分 | C5: 4
A6: 5 | B6: 矩阵 | C6: 4
A7: 6 | B7: 矩阵的特征值和特征向量 | C7: 4
A8: 7 | B8: 随机事件和概率 | C8: 4
A9: 8 | B9: 数理统计的基本概念 | C9: 4
A10: 9 | B10: 一元函数微分 | C10: 4
A11: 10 | B11: 常微分方程 | C11: 4
A12: 11 | B12: 多元函数积分 | C12: 4
A13: 12 | B13: 无穷级数 | C13: 4
... A30: 23（Ⅲ） | B30: 参数估计 | C30: 4
A32: 解答题合计 | C32: =SUM(C16:C30) -> 94
A33: 全卷合计 | C33: =SUM(C2:C30) -> 150
A35: 来源：2017.pdf（数学一）。题号及小问编号沿用附件；未编号的连续求解任务按原题列为一项。第1—14题各4分，第15—19题各10分，第20—23题各11分。大题分值采用卷面标注；小问分值按难度及工作量估分，并非官方评分细则。解答题合计94分，全卷150分。涉及两个小节时，各分配本行分数的一半。

Sheet 数学-考点分布-2020
A1: 题号 | B1: 考点（即：小节） | C1: 分数
A2: 1 | B2: 函数，极限，连续；一元函数积分 | C2: 4
A3: 2 | B3: 函数，极限，连续；一元函数微分 | C3: 4
A4: 3 | B4: 多元函数微分；向量代数与空间解析几何 | C4: 4
A5: 4 | B5: 无穷级数 | C5: 4
A6: 5 | B6: 矩阵 | C6: 4
A7: 6 | B7: 向量代数与空间解析几何；向量 | C7: 4
A8: 7 | B8: 随机事件和概率 | C8: 4
A9: 8 | B9: 大数定律和中心极限定理 | C9: 4
A10: 9 | B10: 函数，极限，连续 | C10: 4
A11: 10 | B11: 一元函数微分 | C11: 4
A12: 11 | B12: 常微分方程；一元函数积分 | C12: 4
A13: 12 | B13: 多元函数微分；一元函数积分 | C13: 4
... A29: 23（Ⅱ） | B29: 参数估计 | C29: 7
A31: 解答题合计 | C31: =SUM(C16:C29) -> 94
A32: 全卷合计 | C32: =SUM(C2:C29) -> 150
A34: 来源：2020.pdf（数学一）。题号及小问编号沿用附件；未编号的连续求解任务按原题列为一项。第1—14题各4分，第15—19题各10分，第20—23题各11分。大题分值采用卷面标注；小问分值按难度及工作量估分，并非官方评分细则。解答题合计94分，全卷150分。涉及两个小节时，各分配本行分数的一半。

Sheet 数学-考点分布-2021
A1: 题号 | B1: 考点（即：小节） | C1: 分数
A2: 1 | B2: 函数，极限，连续；一元函数微分 | C2: 5
A3: 2 | B3: 多元函数微分 | C3: 5
A4: 3 | B4: 一元函数微分 | C4: 5
A5: 4 | B5: 一元函数积分 | C5: 5
A6: 5 | B6: 二次型 | C6: 5
A7: 6 | B7: 向量 | C7: 5
A8: 7 | B8: 矩阵 | C8: 5
A9: 8 | B9: 随机事件和概率 | C9: 5
A10: 9 | B10: 参数估计；随机变量的数字特征 | C10: 5
A11: 10 | B11: 假设检验；数理统计的基本概念 | C11: 5
A12: 11 | B12: 一元函数积分 | C12: 5
A13: 12 | B13: 一元函数微分 | C13: 5
... A27: 22（3） | B27: 随机变量的数字特征 | C27: 4
A29: 解答题合计 | C29: =SUM(C18:C27) -> 70
A30: 全卷合计 | C30: =SUM(C2:C27) -> 150
A32: 说明：第1—16题按每题5分计；第17—22题及各小问分数为按难度和小问数估计的分配，并非官方评分细则，解答题合计70分。来源：2021.pdf（数学一）。

Sheet 数学-考点分布-2022
A1: 题号 | B1: 考点（即：小节） | C1: 分数
A2: 1 | B2: 函数，极限，连续 | C2: 5
A3: 2 | B3: 多元函数微分 | C3: 5
A4: 3 | B4: 函数，极限，连续 | C4: 5
A5: 4 | B5: 一元函数积分 | C5: 5
A6: 5 | B6: 矩阵的特征值和特征向量 | C6: 5
A7: 6 | B7: 线性方程组；矩阵 | C7: 5
A8: 7 | B8: 向量 | C8: 5
A9: 8 | B9: 随机变量的数字特征 | C9: 5
A10: 9 | B10: 大数定律和中心极限定理；随机变量的数字特征 | C10: 5
A11: 10 | B11: 多维随机变量及其分布；随机变量的数字特征 | C11: 5
A12: 11 | B12: 多元函数微分 | C12: 5
A13: 12 | B13: 一元函数积分 | C13: 5
... A25: 24 | B25: 参数估计；随机变量的数字特征 | C25: 11
A27: 解答题合计 | C27: =SUM(C18:C25) -> 70
A28: 全卷合计 | C28: =SUM(C2:C25) -> 150
A30: 说明：题号沿用附件2022.pdf；其中部分大题的小问已被附件连续编号，按原编号逐项列出。第1—16题每题5分；其余分数为按难度及小问工作量估计的分配，并非官方评分细则，解答题合计70分。

Sheet 数学-考点分布-2023
A1: 题号 | B1: 考点（即：小节） | C1: 分数
A2: 1 | B2: 一元函数微分；函数，极限，连续 | C2: 5
A3: 2 | B3: 常微分方程 | C3: 5
A4: 3 | B4: 一元函数微分；函数，极限，连续 | C4: 5
A5: 4 | B5: 无穷级数 | C5: 5
A6: 5 | B6: 矩阵 | C6: 5
A7: 6 | B7: 矩阵的特征值和特征向量 | C7: 5
A8: 7 | B8: 向量；线性方程组 | C8: 5
A9: 8 | B9: 随机变量的数字特征 | C9: 5
A10: 9 | B10: 数理统计的基本概念 | C10: 5
A11: 10 | B11: 参数估计；随机变量的数字特征 | C11: 5
A12: 11 | B12: 函数，极限，连续；一元函数微分 | C12: 5
A13: 12 | B13: 多元函数微分 | C13: 5
... A28: 27 | B28: 多维随机变量及其分布 | C28: 4
A30: 解答题合计 | C30: =SUM(C18:C28) -> 70
A31: 全卷合计 | C31: =SUM(C2:C28) -> 150
A33: 说明：题号沿用附件2023.pdf；其中部分大题的小问已被附件连续编号，按原编号逐项列出。第1—16题每题5分；其余分数为按难度及小问工作量估计的分配，并非官方评分细则，解答题合计70分。

Sheet 数学-考点分布-2024
A1: 题号 | B1: 考点（即：小节） | C1: 分数
A2: 1 | B2: 一元函数积分；函数，极限，连续 | C2: 5
A3: 2 | B3: 多元函数积分 | C3: 5
A4: 3 | B4: 无穷级数 | C4: 5
A5: 4 | B5: 一元函数微分；函数，极限，连续 | C5: 5
A6: 5 | B6: 线性方程组；矩阵 | C6: 5
A7: 6 | B7: 向量 | C7: 5
A8: 7 | B8: 矩阵的特征值和特征向量 | C8: 5
A9: 8 | B9: 多维随机变量及其分布；随机变量及其分布 | C9: 5
A10: 9 | B10: 多维随机变量及其分布；随机变量的数字特征 | C10: 5
A11: 10 | B11: 多维随机变量及其分布 | C11: 5
A12: 11 | B12: 函数，极限，连续 | C12: 5
A13: 12 | B13: 多元函数微分 | C13: 5
... A26: 25 | B26: 参数估计；随机变量的数字特征 | C26: 5
A28: 解答题合计 | C28: =SUM(C18:C26) -> 70
A29: 全卷合计 | C29: =SUM(C2:C26) -> 150
A31: 说明：题号沿用附件2024.pdf；其中部分大题的小问已被附件连续编号，按原编号逐项列出。第1—16题每题5分；其余分数为按难度及小问工作量估计的分配，并非官方评分细则，解答题合计70分。

Sheet 数学-考点分布-2025
A1: 题号 | B1: 考点（即：小节） | C1: 分数
A2: 1 | B2: 一元函数微分；一元函数积分 | C2: 5
A3: 2 | B3: 无穷级数 | C3: 5
A4: 3 | B4: 函数，极限，连续；一元函数微分 | C4: 5
A5: 4 | B5: 多元函数积分 | C5: 5
A6: 5 | B6: 二次型 | C6: 5
A7: 6 | B7: 线性方程组；向量 | C7: 5
A8: 7 | B8: 矩阵 | C8: 5
A9: 8 | B9: 随机变量的数字特征 | C9: 5
A10: 9 | B10: 随机变量及其分布 | C10: 5
A11: 10 | B11: 假设检验；数理统计的基本概念 | C11: 5
A12: 11 | B12: 函数，极限，连续 | C12: 5
A13: 12 | B13: 无穷级数 | C13: 5
... A25: 24 | B25: 多维随机变量及其分布；随机事件和概率 | C25: 6
A27: 解答题合计 | C27: =SUM(C18:C25) -> 70
A28: 全卷合计 | C28: =SUM(C2:C25) -> 150
A30: 说明：题号沿用附件2025.pdf；其中部分大题的小问已被附件连续编号，按原编号逐项列出。第1—16题每题5分；其余分数为按难度及小问工作量估计的分配，并非官方评分细则，解答题合计70分。

Sheet 408-小节得分-2025
A1: 数据结构（30%，45分）
A2: 基本概念 | B2: 小节得分
B3: 4
A4: 线性表 | B4: 小节得分
B5: 12
A6: 栈、队列和数组 | B6: 小节得分
B7: 2
A8: 树和二叉树 | B8: 小节得分
B9: 6
A10: 图 | B10: 小节得分
B11: 12
A12: 查找 | B12: 小节得分
B13: 6
A14: 排序 | B14: 小节得分
B15: 4
A16: 计算机组成原理（30%，45分）
A17: 计算机系统概述 | B17: 小节得分
B18: 2
A19: 数据的表示和运算 | B19: 小节得分
B20: 14.5
A21: 存储器层次结构 | B21: 小节得分
B22: 12
A23: 指令系统 | B23: 小节得分
B24: 6
A25: 中央处理器（CPU） | B25: 小节得分
B26: 6.5
A27: 总线和输入输出系统 | B27: 小节得分
B28: 4
A29: 操作系统（23.33%，35分）
A30: 操作系统基础 | B30: 小节得分
B31: 7.5
A32: 进程管理 | B32: 小节得分
B33: 11
A34: 内存管理 | B34: 小节得分
B35: 6
A36: 文件管理 | B36: 小节得分
B37: 6
A38: 输入/输出（I/O）管理 | B38: 小节得分
B39: 3.5
A40: 计算机网络（16.67%，25分）
...

Sheet 408-小节得分-2024
A1: 数据结构（30%，45分）
A2: 基本概念 | B2: 小节得分
B3: 0
A4: 线性表 | B4: 小节得分
B5: 2
A6: 栈、队列和数组 | B6: 小节得分
B7: 2
A8: 树和二叉树 | B8: 小节得分
B9: 4
A10: 图 | B10: 小节得分
B11: 15
A12: 查找 | B12: 小节得分
B13: 16
A14: 排序 | B14: 小节得分
B15: 6
A16: 计算机组成原理（30%，45分）
A17: 计算机系统概述 | B17: 小节得分
B18: 0
A19: 数据的表示和运算 | B19: 小节得分
B20: 8.5
A21: 存储器层次结构 | B21: 小节得分
B22: 8.5
A23: 指令系统 | B23: 小节得分
B24: 12.5
A25: 中央处理器（CPU） | B25: 小节得分
B26: 9.5
A27: 总线和输入输出系统 | B27: 小节得分
B28: 6
A29: 操作系统（23.33%，35分）
A30: 操作系统基础 | B30: 小节得分
B31: 2
A32: 进程管理 | B32: 小节得分
B33: 16
A34: 内存管理 | B34: 小节得分
B35: 9
A36: 文件管理 | B36: 小节得分
B37: 4
A38: 输入/输出（I/O）管理 | B38: 小节得分
B39: 4
A40: 计算机网络（16.67%，25分）
...

Sheet 408-小节得分-2023
A1: 数据结构（30%，45分）
A2: 基本概念 | B2: 小节得分
B3: 0
A4: 线性表 | B4: 小节得分
B5: 4
A6: 栈、队列和数组 | B6: 小节得分
B7: 2
A8: 树和二叉树 | B8: 小节得分
B9: 4
A10: 图 | B10: 小节得分
B11: 15
A12: 查找 | B12: 小节得分
B13: 6
A14: 排序 | B14: 小节得分
B15: 14
A16: 计算机组成原理（30%，45分）
A17: 计算机系统概述 | B17: 小节得分
B18: 2
A19: 数据的表示和运算 | B19: 小节得分
B20: 6
A21: 存储器层次结构 | B21: 小节得分
B22: 18
A23: 指令系统 | B23: 小节得分
B24: 9
A25: 中央处理器（CPU） | B25: 小节得分
B26: 6
A27: 总线和输入输出系统 | B27: 小节得分
B28: 4
A29: 操作系统（23.33%，35分）
A30: 操作系统基础 | B30: 小节得分
B31: 7
A32: 进程管理 | B32: 小节得分
B33: 15.5
A34: 内存管理 | B34: 小节得分
B35: 6
A36: 文件管理 | B36: 小节得分
B37: 2
A38: 输入/输出（I/O）管理 | B38: 小节得分
B39: 4.5
A40: 计算机网络（16.67%，25分）
...

Sheet 408-小节得分-2022
A1: 数据结构（30%，45分）
A2: 基本概念 | B2: 小节得分
B3: 5
A4: 线性表 | B4: 小节得分
B5: 0
A6: 栈、队列和数组 | B6: 小节得分
B7: 2
A8: 树和二叉树 | B8: 小节得分
B9: 19.5
A10: 图 | B10: 小节得分
B11: 4
A12: 查找 | B12: 小节得分
B13: 10.5
A14: 排序 | B14: 小节得分
B15: 4
A16: 计算机组成原理（30%，45分）
A17: 计算机系统概述 | B17: 小节得分
B18: 2
A19: 数据的表示和运算 | B19: 小节得分
B20: 8
A21: 存储器层次结构 | B21: 小节得分
B22: 11
A23: 指令系统 | B23: 小节得分
B24: 6
A25: 中央处理器（CPU） | B25: 小节得分
B26: 13
A27: 总线和输入输出系统 | B27: 小节得分
B28: 5
A29: 操作系统（23.33%，35分）
A30: 操作系统基础 | B30: 小节得分
B31: 8
A32: 进程管理 | B32: 小节得分
B33: 14
A34: 内存管理 | B34: 小节得分
B35: 4
A36: 文件管理 | B36: 小节得分
B37: 7
A38: 输入/输出（I/O）管理 | B38: 小节得分
B39: 2
A40: 计算机网络（16.67%，25分）
...

Sheet 408-小节得分-2021
A1: 数据结构（30%，45分）
A2: 基本概念 | B2: 小节得分
B3: 2
A4: 线性表 | B4: 小节得分
B5: 2
A6: 栈、队列和数组 | B6: 小节得分
B7: 4
A8: 树和二叉树 | B8: 小节得分
B9: 6
A10: 图 | B10: 小节得分
B11: 17
A12: 查找 | B12: 小节得分
B13: 4
A14: 排序 | B14: 小节得分
B15: 10
A16: 计算机组成原理（30%，45分）
A17: 计算机系统概述 | B17: 小节得分
B18: 2
A19: 数据的表示和运算 | B19: 小节得分
B20: 6
A21: 存储器层次结构 | B21: 小节得分
B22: 14.5
A23: 指令系统 | B23: 小节得分
B24: 8
A25: 中央处理器（CPU） | B25: 小节得分
B26: 8.5
A27: 总线和输入输出系统 | B27: 小节得分
B28: 6
A29: 操作系统（23.33%，35分）
A30: 操作系统基础 | B30: 小节得分
B31: 8
A32: 进程管理 | B32: 小节得分
B33: 14
A34: 内存管理 | B34: 小节得分
B35: 4
A36: 文件管理 | B36: 小节得分
B37: 3
A38: 输入/输出（I/O）管理 | B38: 小节得分
B39: 6
A40: 计算机网络（16.67%，25分）
...

Sheet 408-小节得分-2020
A1: 数据结构（30%，45分）
A2: 基本概念 | B2: 小节得分
B3: 2
A4: 线性表 | B4: 小节得分
B5: 11
A6: 栈、队列和数组 | B6: 小节得分
B7: 4
A8: 树和二叉树 | B8: 小节得分
B9: 16
A10: 图 | B10: 小节得分
B11: 6
A12: 查找 | B12: 小节得分
B13: 4
A14: 排序 | B14: 小节得分
B15: 2
A16: 计算机组成原理（30%，45分）
A17: 计算机系统概述 | B17: 小节得分
B18: 0
A19: 数据的表示和运算 | B19: 小节得分
B20: 15
A21: 存储器层次结构 | B21: 小节得分
B22: 12
A23: 指令系统 | B23: 小节得分
B24: 4
A25: 中央处理器（CPU） | B25: 小节得分
B26: 8
A27: 总线和输入输出系统 | B27: 小节得分
B28: 6
A29: 操作系统（23.33%，35分）
A30: 操作系统基础 | B30: 小节得分
B31: 2
A32: 进程管理 | B32: 小节得分
B33: 15
A34: 内存管理 | B34: 小节得分
B35: 10
A36: 文件管理 | B36: 小节得分
B37: 6
A38: 输入/输出（I/O）管理 | B38: 小节得分
B39: 2
A40: 计算机网络（16.67%，25分）
...

Sheet 408-小节得分-2019
A1: 数据结构（30%，45分）
A2: 基本概念 | B2: 小节得分
B3: 4
A4: 线性表 | B4: 小节得分
B5: 11
A6: 栈、队列和数组 | B6: 小节得分
B7: 10
A8: 树和二叉树 | B8: 小节得分
B9: 4
A10: 图 | B10: 小节得分
B11: 4
A12: 查找 | B12: 小节得分
B13: 6
A14: 排序 | B14: 小节得分
B15: 6
A16: 计算机组成原理（30%，45分）
A17: 计算机系统概述 | B17: 小节得分
B18: 2
A19: 数据的表示和运算 | B19: 小节得分
B20: 7.5
A21: 存储器层次结构 | B21: 小节得分
B22: 9
A23: 指令系统 | B23: 小节得分
B24: 10
A25: 中央处理器（CPU） | B25: 小节得分
B26: 10.5
A27: 总线和输入输出系统 | B27: 小节得分
B28: 6
A29: 操作系统（23.33%，35分）
A30: 操作系统基础 | B30: 小节得分
B31: 2
A32: 进程管理 | B32: 小节得分
B33: 16
A34: 内存管理 | B34: 小节得分
B35: 8
A36: 文件管理 | B36: 小节得分
B37: 2
A38: 输入/输出（I/O）管理 | B38: 小节得分
B39: 7
A40: 计算机网络（16.67%，25分）
...

Sheet 408-小节得分-2018
A1: 数据结构（30%，45分）
A2: 基本概念 | B2: 小节得分
B3: 2
A4: 线性表 | B4: 小节得分
B5: 11
A6: 栈、队列和数组 | B6: 小节得分
B7: 6
A8: 树和二叉树 | B8: 小节得分
B9: 6
A10: 图 | B10: 小节得分
B11: 12
A12: 查找 | B12: 小节得分
B13: 6
A14: 排序 | B14: 小节得分
B15: 2
A16: 计算机组成原理（30%，45分）
A17: 计算机系统概述 | B17: 小节得分
B18: 2
A19: 数据的表示和运算 | B19: 小节得分
B20: 9
A21: 存储器层次结构 | B21: 小节得分
B22: 17
A23: 指令系统 | B23: 小节得分
B24: 3
A25: 中央处理器（CPU） | B25: 小节得分
B26: 2
A27: 总线和输入输出系统 | B27: 小节得分
B28: 12
A29: 操作系统（23.33%，35分）
A30: 操作系统基础 | B30: 小节得分
B31: 3
A32: 进程管理 | B32: 小节得分
B33: 15
A34: 内存管理 | B34: 小节得分
B35: 6
A36: 文件管理 | B36: 小节得分
B37: 9
A38: 输入/输出（I/O）管理 | B38: 小节得分
B39: 2
A40: 计算机网络（16.67%，25分）
...

Sheet 408-小节得分-2017
A1: 数据结构（30%，45分）
A2: 基本概念 | B2: 小节得分
B3: 2
A4: 线性表 | B4: 小节得分
B5: 0
A6: 栈、队列和数组 | B6: 小节得分
B7: 4
A8: 树和二叉树 | B8: 小节得分
B9: 21
A10: 图 | B10: 小节得分
B11: 10
A12: 查找 | B12: 小节得分
B13: 4
A14: 排序 | B14: 小节得分
B15: 4
A16: 计算机组成原理（30%，45分）
A17: 计算机系统概述 | B17: 小节得分
B18: 2
A19: 数据的表示和运算 | B19: 小节得分
B20: 19
A21: 存储器层次结构 | B21: 小节得分
B22: 4
A23: 指令系统 | B23: 小节得分
B24: 9
A25: 中央处理器（CPU） | B25: 小节得分
B26: 5
A27: 总线和输入输出系统 | B27: 小节得分
B28: 6
A29: 操作系统（23.33%，35分）
A30: 操作系统基础 | B30: 小节得分
B31: 5.5
A32: 进程管理 | B32: 小节得分
B33: 13.5
A34: 内存管理 | B34: 小节得分
B35: 6
A36: 文件管理 | B36: 小节得分
B37: 7
A38: 输入/输出（I/O）管理 | B38: 小节得分
B39: 3
A40: 计算机网络（16.67%，25分）
...

Sheet 408-小节得分-2016
A1: 数据结构（30%，45分）
A2: 基本概念 | B2: 小节得分
A4: 线性表 | B4: 小节得分
A6: 栈、队列和数组 | B6: 小节得分
A8: 树和二叉树 | B8: 小节得分
A10: 图 | B10: 小节得分
A12: 查找 | B12: 小节得分
A14: 排序 | B14: 小节得分
A16: 计算机组成原理（30%，45分）
A17: 计算机系统概述 | B17: 小节得分
A19: 数据的表示和运算 | B19: 小节得分
A21: 存储器层次结构 | B21: 小节得分
A23: 指令系统 | B23: 小节得分
A25: 中央处理器（CPU） | B25: 小节得分
A27: 总线和输入输出系统 | B27: 小节得分
A29: 操作系统（23.33%，35分）
A30: 操作系统基础 | B30: 小节得分
A32: 进程管理 | B32: 小节得分
A34: 内存管理 | B34: 小节得分
A36: 文件管理 | B36: 小节得分
A38: 输入/输出（I/O）管理 | B38: 小节得分
A40: 计算机网络（16.67%，25分）
A41: 计算机网络概述 | B41: 小节得分
A43: 物理层 | B43: 小节得分
A45: 数据链路层 | B45: 小节得分
A47: 网络层 | B47: 小节得分
A49: 传输层 | B49: 小节得分
A51: 应用层 | B51: 小节得分

Sheet 408-考点分布-2025
A1: 题号 | B1: 考点（即：小节） | C1: 分数
A2: 1 | B2: 基本概念 | C2: 2
A3: 2 | B3: 栈、队列和数组 | C3: 2
A4: 3 | B4: 树和二叉树 | C4: 2
A5: 4 | B5: 树和二叉树 | C5: 2
A6: 5 | B6: 树和二叉树 | C6: 2
A7: 6 | B7: 图 | C7: 2
A8: 7 | B8: 查找 | C8: 2
A9: 8 | B9: 查找 | C9: 2
A10: 9 | B10: 查找 | C10: 2
A11: 10 | B11: 排序 | C11: 2
A12: 11 | B12: 排序 | C12: 2
A13: 12 | B13: 数据的表示和运算 | C13: 2
... A61: 47（3） | B61: 网络层 | C61: 3
A63: 解答题合计 | C63: =SUM(C42:C61) -> 70
A64: 全卷合计 | C64: =SUM(C2:C61) -> 150
A66: 来源：真题/408/2025.pdf。各题及小问分值均采用附件标注值，未估分。每道选择题一行，有编号的小问分别列示；同一题最多对应两个核心小节，以中文分号分隔。小节名称按2026年408内容面板。

Sheet 408-考点分布-2024
A1: 题号 | B1: 考点（即：小节） | C1: 分数
A2: 1 | B2: 线性表 | C2: 2
A3: 2 | B3: 栈、队列和数组 | C3: 2
A4: 3 | B4: 树和二叉树 | C4: 2
A5: 4 | B5: 图 | C5: 2
A6: 5 | B6: 查找 | C6: 2
A7: 6 | B7: 查找 | C7: 2
A8: 7 | B8: 查找 | C8: 2
A9: 8 | B9: 排序 | C9: 2
A10: 9 | B10: 树和二叉树 | C10: 2
A11: 10 | B11: 排序 | C11: 2
A12: 11 | B12: 排序 | C12: 2
A13: 12 | B13: 数据的表示和运算 | C13: 2
... A64: 47（5） | B64: 网络层 | C64: 2
A66: 解答题合计 | C66: =SUM(C42:C64) -> 70
A67: 全卷合计 | C67: =SUM(C2:C64) -> 150
A69: 来源：真题/408/2024.pdf。各题及小问分值均采用附件标注值，未估分。每道选择题一行，有编号的小问分别列示；同一题最多对应两个核心小节，以中文分号分隔。小节名称按2026年408内容面板。

Sheet 408-考点分布-2023
A1: 题号 | B1: 考点（即：小节） | C1: 分数
A2: 1 | B2: 线性表 | C2: 2
A3: 2 | B3: 线性表 | C3: 2
A4: 3 | B4: 栈、队列和数组 | C4: 2
A5: 4 | B5: 树和二叉树 | C5: 2
A6: 5 | B6: 树和二叉树 | C6: 2
A7: 6 | B7: 图 | C7: 2
A8: 7 | B8: 查找 | C8: 2
A9: 8 | B9: 查找 | C9: 2
A10: 9 | B10: 查找 | C10: 2
A11: 10 | B11: 排序 | C11: 2
A12: 11 | B12: 排序 | C12: 2
A13: 12 | B13: 计算机系统概述 | C13: 2
... A63: 47（4） | B63: 传输层 | C63: 3
A65: 解答题合计 | C65: =SUM(C42:C63) -> 70
A66: 全卷合计 | C66: =SUM(C2:C63) -> 150
A68: 来源：真题/408/2023.pdf。附件仅标注各大题总分；41—47题全部小问分值按作答量及难度估计，非官方细则，各题小问之和与原题总分一致。每道选择题一行，有编号的小问分别列示；同一题最多对应两个核心小节，以中文分号分隔。小节名称按2026年408内容面板。

Sheet 408-考点分布-2022
A1: 题号 | B1: 考点（即：小节） | C1: 分数
A2: 1 | B2: 基本概念 | C2: 2
A3: 2 | B3: 栈、队列和数组 | C3: 2
A4: 3 | B4: 树和二叉树 | C4: 2
A5: 4 | B5: 树和二叉树 | C5: 2
A6: 5 | B6: 树和二叉树 | C6: 2
A7: 6 | B7: 图 | C7: 2
A8: 7 | B8: 图 | C8: 2
A9: 8 | B9: 查找 | C9: 2
A10: 9 | B10: 查找 | C10: 2
A11: 10 | B11: 排序 | C11: 2
A12: 11 | B12: 排序 | C12: 2
A13: 12 | B13: 计算机系统概述 | C13: 2
... A62: 47（4） | B62: 数据链路层 | C62: 2
A64: 解答题合计 | C64: =SUM(C42:C62) -> 70
A65: 全卷合计 | C65: =SUM(C2:C62) -> 150
A67: 来源：真题/408/2022.pdf。大题分值采用附件标注值；未标注的小问按作答量和难度估分，非官方细则，各题小问之和与原题总分一致。每道选择题一行，有编号的小问分别列示；同一题最多对应两个核心小节，以中文分号分隔。小节名称按2026年408内容面板。

Sheet 408-考点分布-2021
A1: 题号 | B1: 考点（即：小节） | C1: 分数
A2: 1 | B2: 线性表 | C2: 2
A3: 2 | B3: 栈、队列和数组 | C3: 2
A4: 3 | B4: 栈、队列和数组 | C4: 2
A5: 4 | B5: 树和二叉树 | C5: 2
A6: 5 | B6: 树和二叉树 | C6: 2
A7: 6 | B7: 查找 | C7: 2
A8: 7 | B8: 图 | C8: 2
A9: 8 | B9: 图 | C9: 2
A10: 9 | B10: 查找 | C10: 2
A11: 10 | B11: 排序 | C11: 2
A12: 11 | B12: 树和二叉树 | C12: 2
A13: 12 | B13: 计算机系统概述 | C13: 2
... A65: 47（3） | B65: 网络层；数据链路层 | C65: 3
A67: 解答题合计 | C67: =SUM(C42:C65) -> 70
A68: 全卷合计 | C68: =SUM(C2:C65) -> 150
A70: 来源：真题/408/2021.pdf。附件第43题标13分，导致大题合计68分；依据厦门工学院公开同年试卷第7页改按15分。核对来源：https://www.xit.edu.cn/_upload/article/files/c1/ce/26986f79493495bbaacba9738587/0e9fd86a-0d3e-48b9-91a1-485e61cc9cc3.pdf 。各小问按作答量和难度估分，非官方细则；综合题合计70分。每道选择题一行，有编号的小问分别列示；同一题最多对应两个核心小节，以中文分号分隔。小节名称按2026年408内容面板。

Sheet 408-考点分布-2020
A1: 题号 | B1: 考点（即：小节） | C1: 分数
A2: 1 | B2: 栈、队列和数组 | C2: 2
A3: 2 | B3: 栈、队列和数组 | C3: 2
A4: 3 | B4: 树和二叉树 | C4: 2
A5: 4 | B5: 树和二叉树 | C5: 2
A6: 5 | B6: 查找 | C6: 2
A7: 6 | B7: 图 | C7: 2
A8: 7 | B8: 图 | C8: 2
A9: 8 | B9: 图 | C9: 2
A10: 9 | B10: 树和二叉树 | C10: 2
A11: 10 | B11: 查找 | C11: 2
A12: 11 | B12: 排序 | C12: 2
A13: 12 | B13: 中央处理器（CPU） | C13: 2
... A60: 47（2） | B60: 网络层 | C60: 6
A62: 解答题合计 | C62: =SUM(C42:C60) -> 70
A63: 全卷合计 | C63: =SUM(C2:C60) -> 150
A65: 来源：真题/408/2020.pdf。大题分值采用附件标注值；未标注的小问按作答量和难度估分，非官方细则，各题小问之和与原题总分一致。每道选择题一行，有编号的小问分别列示；同一题最多对应两个核心小节，以中文分号分隔。小节名称按2026年408内容面板。

Sheet 408-考点分布-2019
A1: 题号 | B1: 考点（即：小节） | C1: 分数
A2: 1 | B2: 基本概念 | C2: 2
A3: 2 | B3: 树和二叉树 | C3: 2
A4: 3 | B4: 树和二叉树 | C4: 2
A5: 4 | B5: 查找 | C5: 2
A6: 5 | B6: 图 | C6: 2
A7: 6 | B7: 图 | C7: 2
A8: 7 | B8: 排序 | C8: 2
A9: 8 | B9: 查找 | C9: 2
A10: 9 | B10: 查找 | C10: 2
A11: 10 | B11: 排序 | C11: 2
A12: 11 | B12: 排序 | C12: 2
A13: 12 | B13: 计算机系统概述 | C13: 2
... A62: 47（4） | B62: 网络层 | C62: 2
A64: 解答题合计 | C64: =SUM(C42:C62) -> 70
A65: 全卷合计 | C65: =SUM(C2:C62) -> 150
A67: 来源：真题/408/2019.pdf。大题分值采用附件标注值；未标注的小问按作答量和难度估分，非官方细则。第43、46题未分编号小问，分别整题记录8、7分，不再重复拆分。每道选择题一行，有编号的小问分别列示；同一题最多对应两个核心小节，以中文分号分隔。小节名称按2026年408内容面板。

Sheet 408-考点分布-2018
A1: 题号 | B1: 考点（即：小节） | C1: 分数
A2: 1 | B2: 栈、队列和数组 | C2: 2
A3: 2 | B3: 栈、队列和数组 | C3: 2
A4: 3 | B4: 栈、队列和数组 | C4: 2
A5: 4 | B5: 树和二叉树 | C5: 2
A6: 5 | B6: 树和二叉树 | C6: 2
A7: 6 | B7: 查找 | C7: 2
A8: 7 | B8: 图 | C8: 2
A9: 8 | B9: 查找 | C9: 2
A10: 9 | B10: 查找 | C10: 2
A11: 10 | B11: 排序 | C11: 2
A12: 11 | B12: 树和二叉树 | C12: 2
A13: 12 | B13: 计算机系统概述 | C13: 2
... A62: 47（2） | B62: 网络层 | C62: 4
A64: 解答题合计 | C64: =SUM(C42:C62) -> 70
A65: 全卷合计 | C65: =SUM(C2:C62) -> 150
A67: 来源：真题/408/2018.pdf。大题分值采用附件标注值；未标注的小问按作答量和难度估分，非官方细则，各题小问之和与原题总分一致。每道选择题一行，有编号的小问分别列示；同一题最多对应两个核心小节，以中文分号分隔。小节名称按2026年408内容面板。

Sheet 408-考点分布-2017
A1: 题号 | B1: 考点（即：小节） | C1: 分数
A2: 1 | B2: 基本概念 | C2: 2
A3: 2 | B3: 栈、队列和数组 | C3: 2
A4: 3 | B4: 栈、队列和数组 | C4: 2
A5: 4 | B5: 树和二叉树 | C5: 2
A6: 5 | B6: 树和二叉树 | C6: 2
A7: 6 | B7: 树和二叉树 | C7: 2
A8: 7 | B8: 图 | C8: 2
A9: 8 | B9: 查找 | C9: 2
A10: 9 | B10: 查找 | C10: 2
A11: 10 | B11: 排序 | C11: 2
A12: 11 | B12: 排序 | C12: 2
A13: 12 | B13: 计算机系统概述 | C13: 2
... A63: 47（4） | B63: 数据链路层 | C63: 2
A65: 解答题合计 | C65: =SUM(C42:C63) -> 70
A66: 全卷合计 | C66: =SUM(C2:C63) -> 150
A68: 来源：真题/408/2017.pdf。大题分值采用附件标注值；未标注的小问按作答量和难度估分，非官方细则，各题小问之和与原题总分一致。第46题未分编号小问，整题记录8分。每道选择题一行，有编号的小问分别列示；同一题最多对应两个核心小节，以中文分号分隔。小节名称按2026年408内容面板。
