Workbook

Sheet 分数面板
A1: 数学考研面板总分 | B1: =SUM(B3,B21,B35) -> 0
A2: 高等数学（60%，90分）
A3: 总分 | B3: =SUM(F5:V5)*0.01*D5+SUM(F7:X7)*0.01*D7+SUM(F9:P9)*0.01*D9+SUM(F11:Y11)*0.01*D11+SUM(F13:S13)*0.01*D13+SUM(F15:Q15)*0.01*D15+SUM(F17:V17)*0.01*D17+SUM(F19:S19)*0.01*D19 -> 0
A4: 函数，极限，连续 | B4: 小节分数 | C4: 总节点数 | D4: 单节点分数 | E4: 节点 | F4: 函数的概念及表示法 | G4: 函数的有界性、单调性、周期性和奇偶性 | H4: 复合函数、反函数、分段函数和隐函数 | I4: 基本初等函数的性质及其图形 | J4: 初等函数 | K4: 函数关系的建立 | L4: 数列极限与函数极限的定义及其性质 | M4: 函数的左极限和右极限 | N4: 无穷小量和无穷大量的概念及其关系 | O4: 无穷小量的性质及无穷小量的比较 | P4: 极限的四则运算 | Q4: 极限存在的两个准则：单调有界准则和夹逼准则 | R4: 两个重要极限 | S4: 函数连续的概念 | T4: 函数间断点的类型 | U4: 初等函数的连续性 | V4: 闭区间上连续函数的性质
B5: =ROUND('2017'!B3*10%+'2020'!B3*12.5%+'2021'!B3*13.5%+'2022'!B3*14.5%+'2023'!B3*15.5%+'2024'!B3*16.5%+'2025'!B3*17.5%,1) -> 9.2 | C5: =COUNTA(F4:Y4) -> 17 | D5: =ROUND(B5/C5,2) -> 0.54 | E5: 掌握度（0~100） | F5: 0 | G5: 0 | H5: 0 | I5: 0 | J5: 0 | K5: 0 | L5: 0 | M5: 0 | N5: 0 | O5: 0 | P5: 0 | Q5: 0 | R5: 0 | S5: 0 | T5: 0 | U5: 0 | V5: 0
A6: 一元函数微分 | B6: 小节分数 | C6: 总节点数 | D6: 单节点分数 | E6: 节点 | F6: 导数和微分的概念 | G6: 导数的几何意义和物理意义 | H6: 函数的可导性与连续性之间的关系 | I6: 平面曲线的切线和法线 | J6: 导数和微分的四则运算 | K6: 基本初等函数的导数 | L6: 复合函数、反函数、隐函数以及参数方程所确定的函数的微分法 | M6: 高阶导数 | N6: 一阶微分形式的不变性 | O6: 微分中值定理 | P6: 洛必达（L’Hospital）法则 | Q6: 函数单调性的判别 | R6: 函数的极值 | S6: 函数图形的凹凸性、拐点及渐近线 | T6: 函数图形的描绘 | U6: 函数的最大值与最小值 | V6: 弧微分 | W6: 曲率的概念 | X6: 曲率圆与曲率半径
B7: =ROUND('2017'!B5*10%+'2020'!B5*12.5%+'2021'!B5*13.5%+'2022'!B5*14.5%+'2023'!B5*15.5%+'2024'!B5*16.5%+'2025'!B5*17.5%,1) -> 17.6 | C7: =COUNTA(F6:Y6) -> 19 | D7: =ROUND(B7/C7,2) -> 0.93 | E7: 掌握度（0~100） | F7: 0 | G7: 0 | H7: 0 | I7: 0 | J7: 0 | K7: 0 | L7: 0 | M7: 0 | N7: 0 | O7: 0 | P7: 0 | Q7: 0 | R7: 0 | S7: 0 | T7: 0 | U7: 0 | V7: 0 | W7: 0 | X7: 0
A8: 一元函数积分 | B8: 小节分数 | C8: 总节点数 | D8: 单节点分数 | E8: 节点 | F8: 原函数和不定积分的概念 | G8: 不定积分的基本性质 | H8: 基本积分公式 | I8: 定积分的概念和基本性质 | J8: 定积分中值定理 | K8: 积分上限的函数及其导数 | L8: 牛顿-莱布尼茨（Newton-Leibniz）公式 | M8: 不定积分和定积分的换元积分法与分部积分法 | N8: 有理函数、三角函数有理式和简单无理函数的积分 | O8: 反常（广义）积分 | P8: 定积分的应用
B9: =ROUND('2017'!B7*10%+'2020'!B7*12.5%+'2021'!B7*13.5%+'2022'!B7*14.5%+'2023'!B7*15.5%+'2024'!B7*16.5%+'2025'!B7*17.5%,1) -> 9.6 | C9: =COUNTA(F8:Y8) -> 11 | D9: =ROUND(B9/C9,2) -> 0.87 | E9: 掌握度（0~100） | F9: 0 | G9: 0 | H9: 0 | I9: 0 | J9: 0 | K9: 0 | L9: 0 | M9: 0 | N9: 0 | O9: 0 | P9: 0
A10: 向量代数与空间解析几何 | B10: 小节分数 | C10: 总节点数 | D10: 单节点分数 | E10: 节点 | F10: 向量的概念 | G10: 向量的线性运算 | H10: 向量的数量积和向量积 | I10: 向量的混合积 | J10: 两向量垂直、平行的条件 | K10: 两向量的夹角 | L10: 向量的坐标表达式及其运算 | M10: 单位向量 | N10: 方向数与方向余弦 | O10: 曲面方程和空间曲线方程的概念 | P10: 平面方程 | Q10: 直线方程 | R10: 平面与平面、平面与直线、直线与直线的夹角以及平行、垂直的条件 | S10: 点到平面和点到直线的距离 | T10: 球面 | U10: 柱面 | V10: 旋转曲面 | W10: 常用的二次曲面方程及其图形 | X10: 空间曲线的参数方程和一般方程 | Y10: 空间曲线在坐标面上的投影曲线方程
B11: =ROUND('2017'!B9*10%+'2020'!B9*12.5%+'2021'!B9*13.5%+'2022'!B9*14.5%+'2023'!B9*15.5%+'2024'!B9*16.5%+'2025'!B9*17.5%,1) -> 3.8 | C11: =COUNTA(F10:Y10) -> 20 | D11: =ROUND(B11/C11,2) -> 0.19 | E11: 掌握度（0~100） | F11: 0 | G11: 0 | H11: 0 | I11: 0 | J11: 0 | K11: 0 | L11: 0 | M11: 0 | N11: 0 | O11: 0 | P11: 0 | Q11: 0 | R11: 0 | S11: 0 | T11: 0 | U11: 0 | V11: 0 | W11: 0 | X11: 0 | Y11: 0
A12: 多元函数微分 | B12: 小节分数 | C12: 总节点数 | D12: 单节点分数 | E12: 节点 | F12: 多元函数的概念 | G12: 二元函数的几何意义 | H12: 二元函数的极限与连续的概念 | I12: 有界闭区域上多元连续函数的性质 | J12: 多元函数的偏导数和全微分 | K12: 全微分存在的必要条件和充分条件 | L12: 多元复合函数、隐函数的求导法 | M12: 二阶偏导数 | N12: 方向导数和梯度 | O12: 空间曲线的切线和法平面 | P12: 曲面的切平面和法线 | Q12: 二元函数的二阶泰勒公式 | R12: 多元函数的极值和条件极值 | S12: 多元函数的最大值、最小值及其简单应用
B13: =ROUND('2017'!B11*10%+'2020'!B11*12.5%+'2021'!B11*13.5%+'2022'!B11*14.5%+'2023'!B11*15.5%+'2024'!B11*16.5%+'2025'!B11*17.5%,1) -> 14.2 | C13: =COUNTA(F12:Y12) -> 14 | D13: =ROUND(B13/C13,2) -> 1.01 | E13: 掌握度（0~100） | F13: 0 | G13: 0 | H13: 0 | I13: 0 | J13: 0 | K13: 0 | L13: 0 | M13: 0 | N13: 0 | O13: 0 | P13: 0 | Q13: 0 | R13: 0 | S13: 0
A14: 多元函数积分 | B14: 小节分数 | C14: 总节点数 | D14: 单节点分数 | E14: 节点 | F14: 二重积分与三重积分的概念、性质、计算和应用 | G14: 两类曲线积分的概念、性质及计算 | H14: 两类曲线积分的关系 | I14: 格林（Green）公式 | J14: 平面曲线积分与路径无关的条件 | K14: 二元函数全微分的原函数 | L14: 两类曲面积分的概念、性质及计算 | M14: 两类曲面积分的关系 | N14: 高斯（Gauss）公式 | O14: 斯托克斯（Stokes）公式 | P14: 散度、旋度的概念及计算 | Q14: 曲线积分和曲面积分的应用
B15: =ROUND('2017'!B13*10%+'2020'!B13*12.5%+'2021'!B13*13.5%+'2022'!B13*14.5%+'2023'!B13*15.5%+'2024'!B13*16.5%+'2025'!B13*17.5%,1) -> 18 | C15: =COUNTA(F14:Y14) -> 12 | D15: =ROUND(B15/C15,2) -> 1.5 | E15: 掌握度（0~100） | F15: 0 | G15: 0 | H15: 0 | I15: 0 | J15: 0 | K15: 0 | L15: 0 | M15: 0 | N15: 0 | O15: 0 | P15: 0 | Q15: 0
A16: 无穷级数 | B16: 小节分数 | C16: 总节点数 | D16: 单节点分数 | E16: 节点 | F16: 常数项级数的收敛与发散的概念 | G16: 收敛级数的和的概念 | H16: 级数的基本性质与收敛的必要条件 | I16: 几何级数与p级数及其收敛性 | J16: 正项级数收敛性的判别法 | K16: 交错级数与莱布尼茨定理 | L16: 任意项级数的绝对收敛与条件收敛 | M16: 函数项级数的收敛域与和函数的概念 | N16: 幂级数及其收敛半径、收敛区间（指开区间）和收敛域 | O16: 幂级数的和函数 | P16: 幂级数在其收敛区间内的基本性质 | Q16: 简单幂级数的和函数的求法 | R16: 初等函数的幂级数展开式 | S16: 函数的傅里叶（Fourier）系数与傅里叶级数 | T16: 狄利克雷（Dirichlet）定理 | U16: 函数在[-l，l]上的傅里叶级数 | V16: 函数在[0，l]上的正弦级数和余弦级数
B17: =ROUND('2017'!B15*10%+'2020'!B15*12.5%+'2021'!B15*13.5%+'2022'!B15*14.5%+'2023'!B15*15.5%+'2024'!B15*16.5%+'2025'!B15*17.5%,1) -> 8.4 | C17: =COUNTA(F16:Y16) -> 17 | D17: =ROUND(B17/C17,2) -> 0.49 | E17: 掌握度（0~100） | F17: 0 | G17: 0 | H17: 0 | I17: 0 | J17: 0 | K17: 0 | L17: 0 | M17: 0 | N17: 0 | O17: 0 | P17: 0 | Q17: 0 | R17: 0 | S17: 0 | T17: 0 | U17: 0 | V17: 0
A18: 常微分方程 | B18: 小节分数 | C18: 总节点数 | D18: 单节点分数 | E18: 节点 | F18: 常微分方程的基本概念 | G18: 变量可分离的微分方程 | H18: 齐次微分方程 | I18: 一阶线性微分方程 | J18: 伯努利（Bernoulli）方程 | K18: 全微分方程 | L18: 可用简单的变量代换求解的某些微分方程 | M18: 可降阶的高阶微分方程 | N18: 线性微分方程解的性质及解的结构定理 | O18: 二阶常系数齐次线性微分方程 | P18: 高于二阶的某些常系数齐次线性微分方程 | Q18: 简单的二阶常系数非齐次线性微分方程 | R18: 欧拉（Euler）方程 | S18: 微分方程的简单应用
B19: =ROUND('2017'!B17*10%+'2020'!B17*12.5%+'2021'!B17*13.5%+'2022'!B17*14.5%+'2023'!B17*15.5%+'2024'!B17*16.5%+'2025'!B17*17.5%,1) -> 5.9 | C19: =COUNTA(F18:Y18) -> 14 | D19: =ROUND(B19/C19,2) -> 0.42 | E19: 掌握度（0~100） | F19: 0 | G19: 0 | H19: 0 | I19: 0 | J19: 0 | K19: 0 | L19: 0 | M19: 0 | N19: 0 | O19: 0 | P19: 0 | Q19: 0 | R19: 0 | S19: 0
A20: 线性代数（20%，30分）
A21: 总分 | B21: =SUM(F23:G23)*0.01*D23+SUM(F25:S25)*0.01*D25+SUM(F27:S27)*0.01*D27+SUM(F29:L29)*0.01*D29+SUM(F31:I31)*0.01*D31+SUM(F33:L33)*0.01*D33 -> 0
A22: 行列式 | B22: 小节分数 | C22: 总节点数 | D22: 单节点分数 | E22: 节点 | F22: 行列式的概念和基本性质 | G22: 行列式按行（列）展开定理
B23: =ROUND('2017'!B20*10%+'2020'!B20*12.5%+'2021'!B20*13.5%+'2022'!B20*14.5%+'2023'!B20*15.5%+'2024'!B20*16.5%+'2025'!B20*17.5%,1) -> 0.8 | C23: =COUNTA(F22:Y22) -> 2 | D23: =ROUND(B23/C23,2) -> 0.4 | E23: 掌握度（0~100） | F23: 0 | G23: 0
A24: 矩阵 | B24: 小节分数 | C24: 总节点数 | D24: 单节点分数 | E24: 节点 | F24: 矩阵的概念 | G24: 矩阵的线性运算 | H24: 矩阵的乘法 | I24: 方阵的幂 | J24: 方阵乘积的行列式 | K24: 矩阵的转置 | L24: 逆矩阵的概念和性质 | M24: 矩阵可逆的充分必要条件 | N24: 伴随矩阵 | O24: 矩阵的初等变换 | P24: 初等矩阵 | Q24: 矩阵的秩 | R24: 矩阵的等价 | S24: 分块矩阵及其运算
B25: =ROUND('2017'!B22*10%+'2020'!B22*12.5%+'2021'!B22*13.5%+'2022'!B22*14.5%+'2023'!B22*15.5%+'2024'!B22*16.5%+'2025'!B22*17.5%,1) -> 7.1 | C25: =COUNTA(F24:Y24) -> 14 | D25: =ROUND(B25/C25,2) -> 0.51 | E25: 掌握度（0~100） | F25: 0 | G25: 0 | H25: 0 | I25: 0 | J25: 0 | K25: 0 | L25: 0 | M25: 0 | N25: 0 | O25: 0 | P25: 0 | Q25: 0 | R25: 0 | S25: 0
A26: 向量 | B26: 小节分数 | C26: 总节点数 | D26: 单节点分数 | E26: 节点 | F26: 向量的概念 | G26: 向量的线性组合与线性表示 | H26: 向量组的线性相关与线性无关 | I26: 向量组的极大线性无关组 | J26: 等价向量组 | K26: 向量组的秩 | L26: 向量组的秩与矩阵的秩之间的关系 | M26: 向量空间及其相关概念 | N26: n维向量空间的基变换和坐标变换 | O26: 过渡矩阵 | P26: 向量的内积 | Q26: 线性无关向量组的正交规范化方法 | R26: 规范正交基 | S26: 正交矩阵及其性质
B27: =ROUND('2017'!B24*10%+'2020'!B24*12.5%+'2021'!B24*13.5%+'2022'!B24*14.5%+'2023'!B24*15.5%+'2024'!B24*16.5%+'2025'!B24*17.5%,1) -> 4.5 | C27: =COUNTA(F26:Y26) -> 14 | D27: =ROUND(B27/C27,2) -> 0.32 | E27: 掌握度（0~100） | F27: 0 | G27: 0 | H27: 0 | I27: 0 | J27: 0 | K27: 0 | L27: 0 | M27: 0 | N27: 0 | O27: 0 | P27: 0 | Q27: 0 | R27: 0 | S27: 0
A28: 线性方程组 | B28: 小节分数 | C28: 总节点数 | D28: 单节点分数 | E28: 节点 | F28: 线性方程组的克拉默（Cramer）法则 | G28: 齐次线性方程组有非零解的充分必要条件 | H28: 非齐次线性方程组有解的充分必要条件 | I28: 线性方程组解的性质和解的结构 | J28: 齐次线性方程组的基础解系和通解 | K28: 解空间 | L28: 非齐次线性方程组的通解
B29: =ROUND('2017'!B26*10%+'2020'!B26*12.5%+'2021'!B26*13.5%+'2022'!B26*14.5%+'2023'!B26*15.5%+'2024'!B26*16.5%+'2025'!B26*17.5%,1) -> 3.5 | C29: =COUNTA(F28:Y28) -> 7 | D29: =ROUND(B29/C29,2) -> 0.5 | E29: 掌握度（0~100） | F29: 0 | G29: 0 | H29: 0 | I29: 0 | J29: 0 | K29: 0 | L29: 0
A30: 矩阵的特征值和特征向量 | B30: 小节分数 | C30: 总节点数 | D30: 单节点分数 | E30: 节点 | F30: 矩阵的特征值和特征向量的概念、性质 | G30: 相似变换、相似矩阵的概念及性质 | H30: 矩阵可相似对角化的充分必要条件及相似对角矩阵 | I30: 实对称矩阵的特征值、特征向量及其相似对角矩阵
B31: =ROUND('2017'!B28*10%+'2020'!B28*12.5%+'2021'!B28*13.5%+'2022'!B28*14.5%+'2023'!B28*15.5%+'2024'!B28*16.5%+'2025'!B28*17.5%,1) -> 9.3 | C31: =COUNTA(F30:Y30) -> 4 | D31: =ROUND(B31/C31,2) -> 2.33 | E31: 掌握度（0~100） | F31: 0 | G31: 0 | H31: 0 | I31: 0
A32: 二次型 | B32: 小节分数 | C32: 总节点数 | D32: 单节点分数 | E32: 节点 | F32: 二次型及其矩阵表示 | G32: 合同变换与合同矩阵 | H32: 二次型的秩 | I32: 惯性定理 | J32: 二次型的标准形和规范形 | K32: 用正交变换和配方法化二次型为标准形 | L32: 二次型及其矩阵的正定性
B33: =ROUND('2017'!B30*10%+'2020'!B30*12.5%+'2021'!B30*13.5%+'2022'!B30*14.5%+'2023'!B30*15.5%+'2024'!B30*16.5%+'2025'!B30*17.5%,1) -> 6.4 | C33: =COUNTA(F32:Y32) -> 7 | D33: =ROUND(B33/C33,2) -> 0.91 | E33: 掌握度（0~100） | F33: 0 | G33: 0 | H33: 0 | I33: 0 | J33: 0 | K33: 0 | L33: 0
A34: 概率论（20%，30分）
A35: 总分 | B35: =SUM(F37:P37)*0.01*D37+SUM(F39:K39)*0.01*D39+SUM(F41:K41)*0.01*D41+SUM(F43:H43)*0.01*D43+SUM(F45:K45)*0.01*D45+SUM(F47:P47)*0.01*D47+SUM(F49:M49)*0.01*D49+SUM(F51:H51)*0.01*D51 -> 0
A36: 随机事件和概率 | B36: 小节分数 | C36: 总节点数 | D36: 单节点分数 | E36: 节点 | F36: 随机事件与样本空间 | G36: 事件的关系与运算 | H36: 完备事件组 | I36: 概率的概念 | J36: 概率的基本性质 | K36: 古典型概率 | L36: 几何型概率 | M36: 条件概率 | N36: 概率的基本公式 | O36: 事件的独立性 | P36: 独立重复试验
B37: =ROUND('2017'!B33*10%+'2020'!B33*12.5%+'2021'!B33*13.5%+'2022'!B33*14.5%+'2023'!B33*15.5%+'2024'!B33*16.5%+'2025'!B33*17.5%,1) -> 4.8 | C37: =COUNTA(F36:Y36) -> 11 | D37: =ROUND(B37/C37,2) -> 0.44 | E37: 掌握度（0~100） | F37: 0 | G37: 0 | H37: 0 | I37: 0 | J37: 0 | K37: 0 | L37: 0 | M37: 0 | N37: 0 | O37: 0 | P37: 0
A38: 随机变量及其分布 | B38: 小节分数 | C38: 总节点数 | D38: 单节点分数 | E38: 节点 | F38: 随机变量 | G38: 随机变量分布函数的概念及其性质 | H38: 离散型随机变量的概率分布 | I38: 连续型随机变量的概率密度 | J38: 常见随机变量的分布 | K38: 随机变量函数的分布
B39: =ROUND('2017'!B35*10%+'2020'!B35*12.5%+'2021'!B35*13.5%+'2022'!B35*14.5%+'2023'!B35*15.5%+'2024'!B35*16.5%+'2025'!B35*17.5%,1) -> 4.1 | C39: =COUNTA(F38:Y38) -> 6 | D39: =ROUND(B39/C39,2) -> 0.68 | E39: 掌握度（0~100） | F39: 0 | G39: 0 | H39: 0 | I39: 0 | J39: 0 | K39: 0
A40: 多维随机变量及其分布 | B40: 小节分数 | C40: 总节点数 | D40: 单节点分数 | E40: 节点 | F40: 多维随机变量及其分布 | G40: 二维离散型随机变量的概率分布、边缘分布和条件分布 | H40: 二维连续型随机变量的概率密度、边缘概率密度和条件密度 | I40: 随机变量的独立性和不相关性 | J40: 常用二维随机变量的分布 | K40: 两个及两个以上随机变量简单函数的分布
...

Sheet 2025
A1: 高等数学（60%，90分）
A2: 函数，极限，连续 | B2: 小节得分
B3: 7.5
A4: 一元函数微分 | B4: 小节得分
B5: 17
A6: 一元函数积分 | B6: 小节得分
B7: 12.5
A8: 向量代数与空间解析几何 | B8: 小节得分
B9: 7
A10: 多元函数微分 | B10: 小节得分
B11: 11
A12: 多元函数积分 | B12: 小节得分
B13: 17
A14: 无穷级数 | B14: 小节得分
B15: 10
A16: 常微分方程 | B16: 小节得分
B17: 6
A18: 线性代数（20%，30分）
A19: 行列式 | B19: 小节得分
B20: 0
A21: 矩阵 | B21: 小节得分
B22: 7.5
A23: 向量 | B23: 小节得分
B24: 2.5
A25: 线性方程组 | B25: 小节得分
B26: 8.5
A27: 矩阵的特征值和特征向量 | B27: 小节得分
B28: 7.5
A29: 二次型 | B29: 小节得分
B30: 5
A31: 概率论（20%，30分）
A32: 随机事件和概率 | B32: 小节得分
B33: 8
A34: 随机变量及其分布 | B34: 小节得分
B35: 7.5
A36: 多维随机变量及其分布 | B36: 小节得分
B37: 3
A38: 随机变量的数字特征 | B38: 小节得分
B39: 7.5
A40: 大数定律和中心极限定理 | B40: 小节得分
...

Sheet 2024
A1: 高等数学（60%，90分）
A2: 函数，极限，连续 | B2: 小节得分
B3: 12.5
A4: 一元函数微分 | B4: 小节得分
B5: 12.5
A6: 一元函数积分 | B6: 小节得分
B7: 4.5
A8: 向量代数与空间解析几何 | B8: 小节得分
B9: 6
A10: 多元函数微分 | B10: 小节得分
B11: 17
A12: 多元函数积分 | B12: 小节得分
B13: 23
A14: 无穷级数 | B14: 小节得分
B15: 7.5
A16: 常微分方程 | B16: 小节得分
B17: 5
A18: 线性代数（20%，30分）
A19: 行列式 | B19: 小节得分
B20: 0
A21: 矩阵 | B21: 小节得分
B22: 8
A23: 向量 | B23: 小节得分
B24: 5
A25: 线性方程组 | B25: 小节得分
B26: 2.5
A27: 矩阵的特征值和特征向量 | B27: 小节得分
B28: 10.5
A29: 二次型 | B29: 小节得分
B30: 5
A31: 概率论（20%，30分）
A32: 随机事件和概率 | B32: 小节得分
B33: 5
A34: 随机变量及其分布 | B34: 小节得分
B35: 2.5
A36: 多维随机变量及其分布 | B36: 小节得分
B37: 10
A38: 随机变量的数字特征 | B38: 小节得分
B39: 5
A40: 大数定律和中心极限定理 | B40: 小节得分
...

Sheet 2023
A1: 高等数学（60%，90分）
A2: 函数，极限，连续 | B2: 小节得分
B3: 7.5
A4: 一元函数微分 | B4: 小节得分
B5: 25.5
A6: 一元函数积分 | B6: 小节得分
B7: 8.5
A8: 向量代数与空间解析几何 | B8: 小节得分
B9: 0
A10: 多元函数微分 | B10: 小节得分
B11: 17
A12: 多元函数积分 | B12: 小节得分
B13: 12
A14: 无穷级数 | B14: 小节得分
B15: 10
A16: 常微分方程 | B16: 小节得分
B17: 7.5
A18: 线性代数（20%，30分）
A19: 行列式 | B19: 小节得分
B20: 0
A21: 矩阵 | B21: 小节得分
B22: 5
A23: 向量 | B23: 小节得分
B24: 7.5
A25: 线性方程组 | B25: 小节得分
B26: 2.5
A27: 矩阵的特征值和特征向量 | B27: 小节得分
B28: 7
A29: 二次型 | B29: 小节得分
B30: 9
A31: 概率论（20%，30分）
A32: 随机事件和概率 | B32: 小节得分
B33: 0
A34: 随机变量及其分布 | B34: 小节得分
B35: 2.5
A36: 多维随机变量及其分布 | B36: 小节得分
B37: 11.5
A38: 随机变量的数字特征 | B38: 小节得分
B39: 9.5
A40: 大数定律和中心极限定理 | B40: 小节得分
...

Sheet 2022
A1: 高等数学（60%，90分）
A2: 函数，极限，连续 | B2: 小节得分
B3: 10
A4: 一元函数微分 | B4: 小节得分
B5: 12
A6: 一元函数积分 | B6: 小节得分
B7: 16
A8: 向量代数与空间解析几何 | B8: 小节得分
B9: 0
A10: 多元函数微分 | B10: 小节得分
B11: 15
A12: 多元函数积分 | B12: 小节得分
B13: 24
A14: 无穷级数 | B14: 小节得分
B15: 5
A16: 常微分方程 | B16: 小节得分
B17: 6
A18: 线性代数（20%，30分）
A19: 行列式 | B19: 小节得分
B20: 0
A21: 矩阵 | B21: 小节得分
B22: 7.5
A23: 向量 | B23: 小节得分
B24: 5
A25: 线性方程组 | B25: 小节得分
B26: 4
A27: 矩阵的特征值和特征向量 | B27: 小节得分
B28: 8
A29: 二次型 | B29: 小节得分
B30: 6.5
A31: 概率论（20%，30分）
A32: 随机事件和概率 | B32: 小节得分
B33: 5
A34: 随机变量及其分布 | B34: 小节得分
B35: 0
A36: 多维随机变量及其分布 | B36: 小节得分
B37: 2.5
A38: 随机变量的数字特征 | B38: 小节得分
B39: 15.5
A40: 大数定律和中心极限定理 | B40: 小节得分
...

Sheet 2021
A1: 高等数学（60%，90分）
A2: 函数，极限，连续 | B2: 小节得分
B3: 7.5
A4: 一元函数微分 | B4: 小节得分
B5: 17.5
A6: 一元函数积分 | B6: 小节得分
B7: 10
A8: 向量代数与空间解析几何 | B8: 小节得分
B9: 6
A10: 多元函数微分 | B10: 小节得分
B11: 11
A12: 多元函数积分 | B12: 小节得分
B13: 17
A14: 无穷级数 | B14: 小节得分
B15: 12
A16: 常微分方程 | B16: 小节得分
B17: 5
A18: 线性代数（20%，30分）
A19: 行列式 | B19: 小节得分
B20: 2.5
A21: 矩阵 | B21: 小节得分
B22: 7.5
A23: 向量 | B23: 小节得分
B24: 5
A25: 线性方程组 | B25: 小节得分
B26: 0
A27: 矩阵的特征值和特征向量 | B27: 小节得分
B28: 9
A29: 二次型 | B29: 小节得分
B30: 8
A31: 概率论（20%，30分）
A32: 随机事件和概率 | B32: 小节得分
B33: 5
A34: 随机变量及其分布 | B34: 小节得分
B35: 8
A36: 多维随机变量及其分布 | B36: 小节得分
B37: 2.5
A38: 随机变量的数字特征 | B38: 小节得分
B39: 9
A40: 大数定律和中心极限定理 | B40: 小节得分
...

Sheet 2020
A1: 高等数学（60%，90分）
A2: 函数，极限，连续 | B2: 小节得分
B3: 8
A4: 一元函数微分 | B4: 小节得分
B5: 16
A6: 一元函数积分 | B6: 小节得分
B7: 6
A8: 向量代数与空间解析几何 | B8: 小节得分
B9: 4
A10: 多元函数微分 | B10: 小节得分
B11: 14
A12: 多元函数积分 | B12: 小节得分
B13: 20
A14: 无穷级数 | B14: 小节得分
B15: 9
A16: 常微分方程 | B16: 小节得分
B17: 7
A18: 线性代数（20%，30分）
A19: 行列式 | B19: 小节得分
B20: 4
A21: 矩阵 | B21: 小节得分
B22: 6
A23: 向量 | B23: 小节得分
B24: 4
A25: 线性方程组 | B25: 小节得分
B26: 0
A27: 矩阵的特征值和特征向量 | B27: 小节得分
B28: 12.5
A29: 二次型 | B29: 小节得分
B30: 5.5
A31: 概率论（20%，30分）
A32: 随机事件和概率 | B32: 小节得分
B33: 6
A34: 随机变量及其分布 | B34: 小节得分
B35: 2
A36: 多维随机变量及其分布 | B36: 小节得分
B37: 11
A38: 随机变量的数字特征 | B38: 小节得分
B39: 4
A40: 大数定律和中心极限定理 | B40: 小节得分
...

Sheet 2019
A1: 高等数学（60%，90分）
A2: 函数，极限，连续 | B2: 小节得分
A4: 一元函数微分 | B4: 小节得分
A6: 一元函数积分 | B6: 小节得分
A8: 向量代数与空间解析几何 | B8: 小节得分
A10: 多元函数微分 | B10: 小节得分
A12: 多元函数积分 | B12: 小节得分
A14: 无穷级数 | B14: 小节得分
A16: 常微分方程 | B16: 小节得分
A18: 线性代数（20%，30分）
A19: 行列式 | B19: 小节得分
A21: 矩阵 | B21: 小节得分
A23: 向量 | B23: 小节得分
A25: 线性方程组 | B25: 小节得分
A27: 矩阵的特征值和特征向量 | B27: 小节得分
A29: 二次型 | B29: 小节得分
A31: 概率论（20%，30分）
A32: 随机事件和概率 | B32: 小节得分
A34: 随机变量及其分布 | B34: 小节得分
A36: 多维随机变量及其分布 | B36: 小节得分
A38: 随机变量的数字特征 | B38: 小节得分
A40: 大数定律和中心极限定理 | B40: 小节得分
A42: 数理统计的基本概念 | B42: 小节得分
A44: 参数估计 | B44: 小节得分
A46: 假设检验 | B46: 小节得分

Sheet 2018
A1: 高等数学（60%，90分）
A2: 函数，极限，连续 | B2: 小节得分
A4: 一元函数微分 | B4: 小节得分
A6: 一元函数积分 | B6: 小节得分
A8: 向量代数与空间解析几何 | B8: 小节得分
A10: 多元函数微分 | B10: 小节得分
A12: 多元函数积分 | B12: 小节得分
A14: 无穷级数 | B14: 小节得分
A16: 常微分方程 | B16: 小节得分
A18: 线性代数（20%，30分）
A19: 行列式 | B19: 小节得分
A21: 矩阵 | B21: 小节得分
A23: 向量 | B23: 小节得分
A25: 线性方程组 | B25: 小节得分
A27: 矩阵的特征值和特征向量 | B27: 小节得分
A29: 二次型 | B29: 小节得分
A31: 概率论（20%，30分）
A32: 随机事件和概率 | B32: 小节得分
A34: 随机变量及其分布 | B34: 小节得分
A36: 多维随机变量及其分布 | B36: 小节得分
A38: 随机变量的数字特征 | B38: 小节得分
A40: 大数定律和中心极限定理 | B40: 小节得分
A42: 数理统计的基本概念 | B42: 小节得分
A44: 参数估计 | B44: 小节得分
A46: 假设检验 | B46: 小节得分

Sheet 2017
A1: 高等数学（60%，90分）
A2: 函数，极限，连续 | B2: 小节得分
B3: 12
A4: 一元函数微分 | B4: 小节得分
B5: 25
A6: 一元函数积分 | B6: 小节得分
B7: 9
A8: 向量代数与空间解析几何 | B8: 小节得分
B9: 3
A10: 多元函数微分 | B10: 小节得分
B11: 14
A12: 多元函数积分 | B12: 小节得分
B13: 11
A14: 无穷级数 | B14: 小节得分
B15: 4
A16: 常微分方程 | B16: 小节得分
B17: 4
A18: 线性代数（20%，30分）
A19: 行列式 | B19: 小节得分
B20: 0
A21: 矩阵 | B21: 小节得分
B22: 8.5
A23: 向量 | B23: 小节得分
B24: 2
A25: 线性方程组 | B25: 小节得分
B26: 6
A27: 矩阵的特征值和特征向量 | B27: 小节得分
B28: 12
A29: 二次型 | B29: 小节得分
B30: 5.5
A31: 概率论（20%，30分）
A32: 随机事件和概率 | B32: 小节得分
B33: 4
A34: 随机变量及其分布 | B34: 小节得分
B35: 7
A36: 多维随机变量及其分布 | B36: 小节得分
B37: 7
A38: 随机变量的数字特征 | B38: 小节得分
B39: 4
A40: 大数定律和中心极限定理 | B40: 小节得分
...

Sheet 2016
A1: 高等数学（60%，90分）
A2: 函数，极限，连续 | B2: 小节得分
A4: 一元函数微分 | B4: 小节得分
A6: 一元函数积分 | B6: 小节得分
A8: 向量代数与空间解析几何 | B8: 小节得分
A10: 多元函数微分 | B10: 小节得分
A12: 多元函数积分 | B12: 小节得分
A14: 无穷级数 | B14: 小节得分
A16: 常微分方程 | B16: 小节得分
A18: 线性代数（20%，30分）
A19: 行列式 | B19: 小节得分
A21: 矩阵 | B21: 小节得分
A23: 向量 | B23: 小节得分
A25: 线性方程组 | B25: 小节得分
A27: 矩阵的特征值和特征向量 | B27: 小节得分
A29: 二次型 | B29: 小节得分
A31: 概率论（20%，30分）
A32: 随机事件和概率 | B32: 小节得分
A34: 随机变量及其分布 | B34: 小节得分
A36: 多维随机变量及其分布 | B36: 小节得分
A38: 随机变量的数字特征 | B38: 小节得分
A40: 大数定律和中心极限定理 | B40: 小节得分
A42: 数理统计的基本概念 | B42: 小节得分
A44: 参数估计 | B44: 小节得分
A46: 假设检验 | B46: 小节得分
