Workbook

Sheet 分数面板
A1: 408考研面板总分 | B1: =SUM(B3,B19,B33,B45) -> 0
A2: 数据结构（30%，45分）
A3: 总分 | B3: =SUM(F5:G5)*D5/100+SUM(F7:I7)*D7/100+SUM(F9:K9)*D9/100+SUM(F11:P11)*D11/100+SUM(F13:O13)*D13/100+SUM(F15:P15)*D15/100+SUM(F17:Q17)*D17/100 -> 0
A4: 基本概念 | B4: 小节分数 | C4: 总节点数 | D4: 单节点分数 | E4: 节点 | F4: 数据结构的基本概念 | G4: 算法的基本概念
B5: =('2017'!B3*$B$61+'2018'!B3*$B$62+'2019'!B3*$B$63+'2020'!B3*$B$64+'2021'!B3*$B$65+'2022'!B3*$B$66+'2023'!B3*$B$67+'2024'!B3*$B$68+'2025'!B3*$B$69)/SUM($B$61:$B$69) -> 2.315 | C5: =COUNTA(F4:G4) -> 2 | D5: =B5/C5 -> 1.1575 | E5: 掌握度（0~100） | F5: 0 | G5: 0
A6: 线性表 | B6: 小节分数 | C6: 总节点数 | D6: 单节点分数 | E6: 节点 | F6: 线性表的基本概念 | G6: 线性表的实现：顺序存储 | H6: 线性表的实现：链式存储 | I6: 线性表的应用
B7: =('2017'!B5*$B$61+'2018'!B5*$B$62+'2019'!B5*$B$63+'2020'!B5*$B$64+'2021'!B5*$B$65+'2022'!B5*$B$66+'2023'!B5*$B$67+'2024'!B5*$B$68+'2025'!B5*$B$69)/SUM($B$61:$B$69) -> 5.88 | C7: =COUNTA(F6:I6) -> 4 | D7: =B7/C7 -> 1.47 | E7: 掌握度（0~100） | F7: 0 | G7: 0 | H7: 0 | I7: 0
A8: 栈、队列和数组 | B8: 小节分数 | C8: 总节点数 | D8: 单节点分数 | E8: 节点 | F8: 栈和队列的基本概念 | G8: 栈和队列的顺序存储结构 | H8: 栈和队列的链式存储结构 | I8: 多维数组的存储 | J8: 特殊矩阵的压缩存储 | K8: 栈、队列和数组的应用
B9: =('2017'!B7*$B$61+'2018'!B7*$B$62+'2019'!B7*$B$63+'2020'!B7*$B$64+'2021'!B7*$B$65+'2022'!B7*$B$66+'2023'!B7*$B$67+'2024'!B7*$B$68+'2025'!B7*$B$69)/SUM($B$61:$B$69) -> 3.79 | C9: =COUNTA(F8:K8) -> 6 | D9: =B9/C9 -> 0.63166667 | E9: 掌握度（0~100） | F9: 0 | G9: 0 | H9: 0 | I9: 0 | J9: 0 | K9: 0
A10: 树和二叉树 | B10: 小节分数 | C10: 总节点数 | D10: 单节点分数 | E10: 节点 | F10: 树的基本概念 | G10: 二叉树的定义及其主要特性 | H10: 二叉树的顺序存储结构和链式存储结构 | I10: 二叉树的遍历 | J10: 线索二叉树的基本概念和构造 | K10: 树的存储结构 | L10: 森林与二叉树的转换 | M10: 树和森林的遍历 | N10: 哈夫曼（Huffman）树和哈夫曼编码 | O10: 并查集及其应用 | P10: 堆及其应用
B11: =('2017'!B9*$B$61+'2018'!B9*$B$62+'2019'!B9*$B$63+'2020'!B9*$B$64+'2021'!B9*$B$65+'2022'!B9*$B$66+'2023'!B9*$B$67+'2024'!B9*$B$68+'2025'!B9*$B$69)/SUM($B$61:$B$69) -> 9.2525 | C11: =COUNTA(F10:P10) -> 11 | D11: =B11/C11 -> 0.84113636 | E11: 掌握度（0~100） | F11: 0 | G11: 0 | H11: 0 | I11: 0 | J11: 0 | K11: 0 | L11: 0 | M11: 0 | N11: 0 | O11: 0 | P11: 0
A12: 图 | B12: 小节分数 | C12: 总节点数 | D12: 单节点分数 | E12: 节点 | F12: 图的基本概念 | G12: 图的存储及基本操作：邻接矩阵 | H12: 图的存储及基本操作：邻接表 | I12: 图的存储及基本操作：邻接多重表、十字链表 | J12: 图的遍历：深度优先搜索 | K12: 图的遍历：广度优先搜索 | L12: 最小（代价）生成树 | M12: 最短路径 | N12: 拓扑排序 | O12: 关键路径
B13: =('2017'!B11*$B$61+'2018'!B11*$B$62+'2019'!B11*$B$63+'2020'!B11*$B$64+'2021'!B11*$B$65+'2022'!B11*$B$66+'2023'!B11*$B$67+'2024'!B11*$B$68+'2025'!B11*$B$69)/SUM($B$61:$B$69) -> 10.77 | C13: =COUNTA(F12:O12) -> 10 | D13: =B13/C13 -> 1.077 | E13: 掌握度（0~100） | F13: 0 | G13: 0 | H13: 0 | I13: 0 | J13: 0 | K13: 0 | L13: 0 | M13: 0 | N13: 0 | O13: 0
A14: 查找 | B14: 小节分数 | C14: 总节点数 | D14: 单节点分数 | E14: 节点 | F14: 查找的基本概念 | G14: 顺序查找法 | H14: 分块查找法 | I14: 折半查找法 | J14: 二叉搜索树 | K14: 平衡二叉树 | L14: 红黑树 | M14: B树及其基本操作、B+树的基本概念 | N14: 散列（Hash）表 | O14: 字符串模式匹配 | P14: 查找算法的分析及应用
B15: =('2017'!B13*$B$61+'2018'!B13*$B$62+'2019'!B13*$B$63+'2020'!B13*$B$64+'2021'!B13*$B$65+'2022'!B13*$B$66+'2023'!B13*$B$67+'2024'!B13*$B$68+'2025'!B13*$B$69)/SUM($B$61:$B$69) -> 7.2075 | C15: =COUNTA(F14:P14) -> 11 | D15: =B15/C15 -> 0.65522727 | E15: 掌握度（0~100） | F15: 0 | G15: 0 | H15: 0 | I15: 0 | J15: 0 | K15: 0 | L15: 0 | M15: 0 | N15: 0 | O15: 0 | P15: 0
A16: 排序 | B16: 小节分数 | C16: 总节点数 | D16: 单节点分数 | E16: 节点 | F16: 排序的基本概念 | G16: 直接插入排序 | H16: 折半插入排序 | I16: 起泡排序（Bubble Sort） | J16: 简单选择排序 | K16: 希尔排序（Shell Sort） | L16: 快速排序 | M16: 堆排序 | N16: 二路归并排序（Merge Sort） | O16: 基数排序 | P16: 外部排序 | Q16: 排序算法的分析与应用
B17: =('2017'!B15*$B$61+'2018'!B15*$B$62+'2019'!B15*$B$63+'2020'!B15*$B$64+'2021'!B15*$B$65+'2022'!B15*$B$66+'2023'!B15*$B$67+'2024'!B15*$B$68+'2025'!B15*$B$69)/SUM($B$61:$B$69) -> 5.92 | C17: =COUNTA(F16:Q16) -> 12 | D17: =B17/C17 -> 0.49333333 | E17: 掌握度（0~100） | F17: 0 | G17: 0 | H17: 0 | I17: 0 | J17: 0 | K17: 0 | L17: 0 | M17: 0 | N17: 0 | O17: 0 | P17: 0 | Q17: 0
A18: 计算机组成原理（30%，45分）
A19: 总分 | B19: =SUM(F21:J21)*D21/100+SUM(F23:N23)*D23/100+SUM(F25:W25)*D25/100+SUM(F27:N27)*D27/100+SUM(F29:T29)*D29/100+SUM(F31:M31)*D31/100 -> 0
A20: 计算机系统概述 | B20: 小节分数 | C20: 总节点数 | D20: 单节点分数 | E20: 节点 | F20: 计算机系统的基本组成 | G20: 计算机硬件的基本组成 | H20: 计算机软件和硬件的关系 | I20: 计算机系统的工作原理：“存储程序”工作方式，高级语言程序与机器语言程序之间的转换，程序和指令的执行过程 | J20: 计算机性能指标：吞吐量、响应时间；CPU时钟周期、主频、CPI、CPU执行时间；MIPS、MFLOPS、GFLOPS、TFLOPS、PFLOPS、EFLOPS、ZFLOPS
B21: =('2017'!B18*$B$61+'2018'!B18*$B$62+'2019'!B18*$B$63+'2020'!B18*$B$64+'2021'!B18*$B$65+'2022'!B18*$B$66+'2023'!B18*$B$67+'2024'!B18*$B$68+'2025'!B18*$B$69)/SUM($B$61:$B$69) -> 1.53 | C21: =COUNTA(F20:J20) -> 5 | D21: =B21/C21 -> 0.306 | E21: 掌握度（0~100） | F21: 0 | G21: 0 | H21: 0 | I21: 0 | J21: 0
A22: 数据的表示和运算 | B22: 小节分数 | C22: 总节点数 | D22: 单节点分数 | E22: 节点 | F22: 进位计数制及其数据之间的相互转换 | G22: 定点数的编码表示 | H22: 基本运算部件：加法器，算术逻辑部件（ALU） | I22: 加/减运算：补码加/减运算器，标志位的生成 | J22: 乘/除运算：乘/除法运算的基本原理，乘法电路和除法电路的基本结构 | K22: 无符号整数的表示和运算 | L22: 带符号整数的表示和运算 | M22: 浮点数的表示：IEEE754标准 | N22: 浮点数的加/减运算
B23: =('2017'!B20*$B$61+'2018'!B20*$B$62+'2019'!B20*$B$63+'2020'!B20*$B$64+'2021'!B20*$B$65+'2022'!B20*$B$66+'2023'!B20*$B$67+'2024'!B20*$B$68+'2025'!B20*$B$69)/SUM($B$61:$B$69) -> 10.2525 | C23: =COUNTA(F22:N22) -> 9 | D23: =B23/C23 -> 1.1391667 | E23: 掌握度（0~100） | F23: 0 | G23: 0 | H23: 0 | I23: 0 | J23: 0 | K23: 0 | L23: 0 | M23: 0 | N23: 0
A24: 存储器层次结构 | B24: 小节分数 | C24: 总节点数 | D24: 单节点分数 | E24: 节点 | F24: 存储器的分类 | G24: 层次化存储器的基本结构 | H24: SRAM存储器 | I24: DRAM存储器 | J24: Flash存储器 | K24: DRAM芯片和内存条 | L24: 多模块存储器 | M24: 主存和CPU之间的连接 | N24: 磁盘存储器 | O24: 固态硬盘（SSD） | P24: Cache的基本原理 | Q24: Cache和主存之间的映射方式 | R24: Cache中主存块的替换算法 | S24: Cache写策略 | T24: 虚拟存储器的基本概念 | U24: 页式虚拟存储器：基本原理，页表，地址转换，TLB（快表） | V24: 段式虚拟存储器的基本原理 | W24: 段页式虚拟存储器的基本原理
B25: =('2017'!B22*$B$61+'2018'!B22*$B$62+'2019'!B22*$B$63+'2020'!B22*$B$64+'2021'!B22*$B$65+'2022'!B22*$B$66+'2023'!B22*$B$67+'2024'!B22*$B$68+'2025'!B22*$B$69)/SUM($B$61:$B$69) -> 11.88 | C25: =COUNTA(F24:W24) -> 18 | D25: =B25/C25 -> 0.66 | E25: 掌握度（0~100） | F25: 0 | G25: 0 | H25: 0 | I25: 0 | J25: 0 | K25: 0 | L25: 0 | M25: 0 | N25: 0 | O25: 0 | P25: 0 | Q25: 0 | R25: 0 | S25: 0 | T25: 0 | U25: 0 | V25: 0 | W25: 0
A26: 指令系统 | B26: 小节分数 | C26: 总节点数 | D26: 单节点分数 | E26: 节点 | F26: 指令系统的基本概念 | G26: 指令格式 | H26: 寻址方式 | I26: 数据的对齐和大小端存放方式 | J26: CISC和RISC的基本概念 | K26: 编译器、汇编器和链接器的基本概念 | L26: 选择结构语句的机器级表示 | M26: 循环结构语句的机器级表示 | N26: 过程（函数）调用对应的机器级表示
B27: =('2017'!B24*$B$61+'2018'!B24*$B$62+'2019'!B24*$B$63+'2020'!B24*$B$64+'2021'!B24*$B$65+'2022'!B24*$B$66+'2023'!B24*$B$67+'2024'!B24*$B$68+'2025'!B24*$B$69)/SUM($B$61:$B$69) -> 7.6 | C27: =COUNTA(F26:N26) -> 9 | D27: =B27/C27 -> 0.84444444 | E27: 掌握度（0~100） | F27: 0 | G27: 0 | H27: 0 | I27: 0 | J27: 0 | K27: 0 | L27: 0 | M27: 0 | N27: 0
A28: 中央处理器（CPU） | B28: 小节分数 | C28: 总节点数 | D28: 单节点分数 | E28: 节点 | F28: CPU的功能和基本结构 | G28: 指令执行过程 | H28: 数据通路的功能和基本结构 | I28: 控制器的功能和工作原理 | J28: 异常和中断的基本概念 | K28: 异常和中断的分类 | L28: 异常和中断的检测与响应 | M28: 指令流水线的基本概念 | N28: 指令流水线的基本实现 | O28: 结构冒险、数据冒险和控制冒险的处理 | P28: 超标量和动态流水线的基本概念 | Q28: SISD、SIMD、MIMD、向量处理器的基本概念 | R28: 硬件多线程的基本概念 | S28: 多核（multi-core）处理器的基本概念 | T28: 共享内存多处理器（SMP）的基本概念
B29: =('2017'!B26*$B$61+'2018'!B26*$B$62+'2019'!B26*$B$63+'2020'!B26*$B$64+'2021'!B26*$B$65+'2022'!B26*$B$66+'2023'!B26*$B$67+'2024'!B26*$B$68+'2025'!B26*$B$69)/SUM($B$61:$B$69) -> 7.7925 | C29: =COUNTA(F28:T28) -> 15 | D29: =B29/C29 -> 0.5195 | E29: 掌握度（0~100） | F29: 0 | G29: 0 | H29: 0 | I29: 0 | J29: 0 | K29: 0 | L29: 0 | M29: 0 | N29: 0 | O29: 0 | P29: 0 | Q29: 0 | R29: 0 | S29: 0 | T29: 0
A30: 总线和输入输出系统 | B30: 小节分数 | C30: 总节点数 | D30: 单节点分数 | E30: 节点 | F30: 总线的基本概念 | G30: 总线的组成及性能指标 | H30: 总线事务和定时 | I30: I/O接口的功能和基本结构 | J30: I/O端口及其编址 | K30: 程序查询方式 | L30: 程序中断方式：中断的基本概念，中断响应过程，中断处理过程，多重中断和中断屏蔽的概念 | M30: DMA方式：DMA控制器的组成，DMA传送过程
B31: =('2017'!B28*$B$61+'2018'!B28*$B$62+'2019'!B28*$B$63+'2020'!B28*$B$64+'2021'!B28*$B$65+'2022'!B28*$B$66+'2023'!B28*$B$67+'2024'!B28*$B$68+'2025'!B28*$B$69)/SUM($B$61:$B$69) -> 5.945 | C31: =COUNTA(F30:M30) -> 8 | D31: =B31/C31 -> 0.743125 | E31: 掌握度（0~100） | F31: 0 | G31: 0 | H31: 0 | I31: 0 | J31: 0 | K31: 0 | L31: 0 | M31: 0
A32: 操作系统（23.33%，35分）
A33: 总分 | B33: =SUM(F35:O35)*D35/100+SUM(F37:Z37)*D37/100+SUM(F39:P39)*D39/100+SUM(F41:S41)*D41/100+SUM(F43:O43)*D43/100 -> 0
A34: 操作系统基础 | B34: 小节分数 | C34: 总节点数 | D34: 单节点分数 | E34: 节点 | F34: 操作系统的基本概念 | G34: 操作系统发展历程 | H34: CPU运行模式：内核模式，用户模式 | I34: 中断和异常的处理 | J34: 系统调用 | K34: 程序的链接与装入 | L34: 程序运行时内存映像与地址空间 | M34: 操作系统结构：分层，模块化，宏内核，微内核，外核 | N34: 操作系统引导 | O34: 虚拟机
B35: =('2017'!B31*$B$61+'2018'!B31*$B$62+'2019'!B31*$B$63+'2020'!B31*$B$64+'2021'!B31*$B$65+'2022'!B31*$B$66+'2023'!B31*$B$67+'2024'!B31*$B$68+'2025'!B31*$B$69)/SUM($B$61:$B$69) -> 5.1025 | C35: =COUNTA(F34:O34) -> 10 | D35: =B35/C35 -> 0.51025 | E35: 掌握度（0~100） | F35: 0 | G35: 0 | H35: 0 | I35: 0 | J35: 0 | K35: 0 | L35: 0 | M35: 0 | N35: 0 | O35: 0
A36: 进程管理 | B36: 小节分数 | C36: 总节点数 | D36: 单节点分数 | E36: 节点 | F36: 进程与线程的基本概念 | G36: 进程/线程的状态与转换 | H36: 线程的实现：内核支持的线程，线程库支持的线程 | I36: 进程与线程的组织与控制 | J36: 进程间通信：共享内存，消息传递，管道，信号 | K36: CPU调度的基本概念 | L36: CPU调度的目标 | M36: CPU调度的实现：调度器/调度程序（scheduler），调度的时机与调度方式（抢占式/非抢占式），闲逛进程，内核级线程与用户级线程调度 | N36: CPU调度算法 | O36: 多处理机调度 | P36: 上下文及其切换机制 | Q36: 同步与互斥的基本概念 | R36: 同步与互斥的基本实现方法：软件方法，硬件方法 | S36: 锁 | T36: 信号量 | U36: 条件变量 | V36: 经典同步问题：生产者-消费者问题，读者-写者问题，哲学家进餐问题等 | W36: 死锁的基本概念 | X36: 死锁预防 | Y36: 死锁避免 | Z36: 死锁检测和解除
B37: =('2017'!B33*$B$61+'2018'!B33*$B$62+'2019'!B33*$B$63+'2020'!B33*$B$64+'2021'!B33*$B$65+'2022'!B33*$B$66+'2023'!B33*$B$67+'2024'!B33*$B$68+'2025'!B33*$B$69)/SUM($B$61:$B$69) -> 14.39 | C37: =COUNTA(F36:Z36) -> 21 | D37: =B37/C37 -> 0.6852381 | E37: 掌握度（0~100） | F37: 0 | G37: 0 | H37: 0 | I37: 0 | J37: 0 | K37: 0 | L37: 0 | M37: 0 | N37: 0 | O37: 0 | P37: 0 | Q37: 0 | R37: 0 | S37: 0 | T37: 0 | U37: 0 | V37: 0 | W37: 0 | X37: 0 | Y37: 0 | Z37: 0
A38: 内存管理 | B38: 小节分数 | C38: 总节点数 | D38: 单节点分数 | E38: 节点 | F38: 内存管理的基本概念：逻辑地址空间与物理地址空间，地址变换，内存共享，内存保护，内存分配与回收 | G38: 连续分配管理方式 | H38: 页式管理 | I38: 段式管理 | J38: 段页式管理 | K38: 虚拟内存的基本概念 | L38: 请求页式管理 | M38: 页框分配与回收 | N38: 页置换算法 | O38: 内存映射文件（Memory-Mapped Files） | P38: 虚拟存储器性能的影响因素及改进方法
B39: =('2017'!B35*$B$61+'2018'!B35*$B$62+'2019'!B35*$B$63+'2020'!B35*$B$64+'2021'!B35*$B$65+'2022'!B35*$B$66+'2023'!B35*$B$67+'2024'!B35*$B$68+'2025'!B35*$B$69)/SUM($B$61:$B$69) -> 6.56 | C39: =COUNTA(F38:P38) -> 11 | D39: =B39/C39 -> 0.59636364 | E39: 掌握度（0~100） | F39: 0 | G39: 0 | H39: 0 | I39: 0 | J39: 0 | K39: 0 | L39: 0 | M39: 0 | N39: 0 | O39: 0 | P39: 0
A40: 文件管理 | B40: 小节分数 | C40: 总节点数 | D40: 单节点分数 | E40: 节点 | F40: 文件的基本概念 | G40: 文件元数据和索引节点（inode） | H40: 文件的操作：建立，删除，打开，关闭，读，写 | I40: 文件的保护 | J40: 文件的逻辑结构 | K40: 文件的物理结构 | L40: 目录的基本概念 | M40: 树形目录 | N40: 目录的操作 | O40: 硬链接和软链接 | P40: 文件系统的全局结构（layout）：文件系统在外存中的结构，文件系统在内存中的结构 | Q40: 外存空闲空间管理方法 | R40: 虚拟文件系统 | S40: 文件系统挂载（mounting）
...

Sheet 2025
A1: 数据结构（30%，45分）
A2: 基本概念 | B2: 小节得分
B3: 4
A4: 线性表 | B4: 小节得分
B5: 12
A6: 栈、队列和数组 | B6: 小节得分
B7: 2
A8: 树和二叉树 | B8: 小节得分
B9: 6
A10: 图 | B10: 小节得分
B11: 12
A12: 查找 | B12: 小节得分
B13: 6
A14: 排序 | B14: 小节得分
B15: 4
A16: 计算机组成原理（30%，45分）
A17: 计算机系统概述 | B17: 小节得分
B18: 2
A19: 数据的表示和运算 | B19: 小节得分
B20: 14.5
A21: 存储器层次结构 | B21: 小节得分
B22: 12
A23: 指令系统 | B23: 小节得分
B24: 6
A25: 中央处理器（CPU） | B25: 小节得分
B26: 6.5
A27: 总线和输入输出系统 | B27: 小节得分
B28: 4
A29: 操作系统（23.33%，35分）
A30: 操作系统基础 | B30: 小节得分
B31: 7.5
A32: 进程管理 | B32: 小节得分
B33: 11
A34: 内存管理 | B34: 小节得分
B35: 6
A36: 文件管理 | B36: 小节得分
B37: 6
A38: 输入/输出（I/O）管理 | B38: 小节得分
B39: 3.5
A40: 计算机网络（16.67%，25分）
...

Sheet 2024
A1: 数据结构（30%，45分）
A2: 基本概念 | B2: 小节得分
B3: 0
A4: 线性表 | B4: 小节得分
B5: 2
A6: 栈、队列和数组 | B6: 小节得分
B7: 2
A8: 树和二叉树 | B8: 小节得分
B9: 4
A10: 图 | B10: 小节得分
B11: 15
A12: 查找 | B12: 小节得分
B13: 16
A14: 排序 | B14: 小节得分
B15: 6
A16: 计算机组成原理（30%，45分）
A17: 计算机系统概述 | B17: 小节得分
B18: 0
A19: 数据的表示和运算 | B19: 小节得分
B20: 8.5
A21: 存储器层次结构 | B21: 小节得分
B22: 8.5
A23: 指令系统 | B23: 小节得分
B24: 12.5
A25: 中央处理器（CPU） | B25: 小节得分
B26: 9.5
A27: 总线和输入输出系统 | B27: 小节得分
B28: 6
A29: 操作系统（23.33%，35分）
A30: 操作系统基础 | B30: 小节得分
B31: 2
A32: 进程管理 | B32: 小节得分
B33: 16
A34: 内存管理 | B34: 小节得分
B35: 9
A36: 文件管理 | B36: 小节得分
B37: 4
A38: 输入/输出（I/O）管理 | B38: 小节得分
B39: 4
A40: 计算机网络（16.67%，25分）
...

Sheet 2023
A1: 数据结构（30%，45分）
A2: 基本概念 | B2: 小节得分
B3: 0
A4: 线性表 | B4: 小节得分
B5: 4
A6: 栈、队列和数组 | B6: 小节得分
B7: 2
A8: 树和二叉树 | B8: 小节得分
B9: 4
A10: 图 | B10: 小节得分
B11: 15
A12: 查找 | B12: 小节得分
B13: 6
A14: 排序 | B14: 小节得分
B15: 14
A16: 计算机组成原理（30%，45分）
A17: 计算机系统概述 | B17: 小节得分
B18: 2
A19: 数据的表示和运算 | B19: 小节得分
B20: 6
A21: 存储器层次结构 | B21: 小节得分
B22: 18
A23: 指令系统 | B23: 小节得分
B24: 9
A25: 中央处理器（CPU） | B25: 小节得分
B26: 6
A27: 总线和输入输出系统 | B27: 小节得分
B28: 4
A29: 操作系统（23.33%，35分）
A30: 操作系统基础 | B30: 小节得分
B31: 7
A32: 进程管理 | B32: 小节得分
B33: 15.5
A34: 内存管理 | B34: 小节得分
B35: 6
A36: 文件管理 | B36: 小节得分
B37: 2
A38: 输入/输出（I/O）管理 | B38: 小节得分
B39: 4.5
A40: 计算机网络（16.67%，25分）
...

Sheet 2022
A1: 数据结构（30%，45分）
A2: 基本概念 | B2: 小节得分
B3: 5
A4: 线性表 | B4: 小节得分
B5: 0
A6: 栈、队列和数组 | B6: 小节得分
B7: 2
A8: 树和二叉树 | B8: 小节得分
B9: 19.5
A10: 图 | B10: 小节得分
B11: 4
A12: 查找 | B12: 小节得分
B13: 10.5
A14: 排序 | B14: 小节得分
B15: 4
A16: 计算机组成原理（30%，45分）
A17: 计算机系统概述 | B17: 小节得分
B18: 2
A19: 数据的表示和运算 | B19: 小节得分
B20: 8
A21: 存储器层次结构 | B21: 小节得分
B22: 11
A23: 指令系统 | B23: 小节得分
B24: 6
A25: 中央处理器（CPU） | B25: 小节得分
B26: 13
A27: 总线和输入输出系统 | B27: 小节得分
B28: 5
A29: 操作系统（23.33%，35分）
A30: 操作系统基础 | B30: 小节得分
B31: 8
A32: 进程管理 | B32: 小节得分
B33: 14
A34: 内存管理 | B34: 小节得分
B35: 4
A36: 文件管理 | B36: 小节得分
B37: 7
A38: 输入/输出（I/O）管理 | B38: 小节得分
B39: 2
A40: 计算机网络（16.67%，25分）
...

Sheet 2021
A1: 数据结构（30%，45分）
A2: 基本概念 | B2: 小节得分
B3: 2
A4: 线性表 | B4: 小节得分
B5: 2
A6: 栈、队列和数组 | B6: 小节得分
B7: 4
A8: 树和二叉树 | B8: 小节得分
B9: 6
A10: 图 | B10: 小节得分
B11: 17
A12: 查找 | B12: 小节得分
B13: 4
A14: 排序 | B14: 小节得分
B15: 10
A16: 计算机组成原理（30%，45分）
A17: 计算机系统概述 | B17: 小节得分
B18: 2
A19: 数据的表示和运算 | B19: 小节得分
B20: 6
A21: 存储器层次结构 | B21: 小节得分
B22: 14.5
A23: 指令系统 | B23: 小节得分
B24: 8
A25: 中央处理器（CPU） | B25: 小节得分
B26: 8.5
A27: 总线和输入输出系统 | B27: 小节得分
B28: 6
A29: 操作系统（23.33%，35分）
A30: 操作系统基础 | B30: 小节得分
B31: 8
A32: 进程管理 | B32: 小节得分
B33: 14
A34: 内存管理 | B34: 小节得分
B35: 4
A36: 文件管理 | B36: 小节得分
B37: 3
A38: 输入/输出（I/O）管理 | B38: 小节得分
B39: 6
A40: 计算机网络（16.67%，25分）
...

Sheet 2020
A1: 数据结构（30%，45分）
A2: 基本概念 | B2: 小节得分
B3: 2
A4: 线性表 | B4: 小节得分
B5: 11
A6: 栈、队列和数组 | B6: 小节得分
B7: 4
A8: 树和二叉树 | B8: 小节得分
B9: 16
A10: 图 | B10: 小节得分
B11: 6
A12: 查找 | B12: 小节得分
B13: 4
A14: 排序 | B14: 小节得分
B15: 2
A16: 计算机组成原理（30%，45分）
A17: 计算机系统概述 | B17: 小节得分
B18: 0
A19: 数据的表示和运算 | B19: 小节得分
B20: 15
A21: 存储器层次结构 | B21: 小节得分
B22: 12
A23: 指令系统 | B23: 小节得分
B24: 4
A25: 中央处理器（CPU） | B25: 小节得分
B26: 8
A27: 总线和输入输出系统 | B27: 小节得分
B28: 6
A29: 操作系统（23.33%，35分）
A30: 操作系统基础 | B30: 小节得分
B31: 2
A32: 进程管理 | B32: 小节得分
B33: 15
A34: 内存管理 | B34: 小节得分
B35: 10
A36: 文件管理 | B36: 小节得分
B37: 6
A38: 输入/输出（I/O）管理 | B38: 小节得分
B39: 2
A40: 计算机网络（16.67%，25分）
...

Sheet 2019
A1: 数据结构（30%，45分）
A2: 基本概念 | B2: 小节得分
B3: 4
A4: 线性表 | B4: 小节得分
B5: 11
A6: 栈、队列和数组 | B6: 小节得分
B7: 10
A8: 树和二叉树 | B8: 小节得分
B9: 4
A10: 图 | B10: 小节得分
B11: 4
A12: 查找 | B12: 小节得分
B13: 6
A14: 排序 | B14: 小节得分
B15: 6
A16: 计算机组成原理（30%，45分）
A17: 计算机系统概述 | B17: 小节得分
B18: 2
A19: 数据的表示和运算 | B19: 小节得分
B20: 7.5
A21: 存储器层次结构 | B21: 小节得分
B22: 9
A23: 指令系统 | B23: 小节得分
B24: 10
A25: 中央处理器（CPU） | B25: 小节得分
B26: 10.5
A27: 总线和输入输出系统 | B27: 小节得分
B28: 6
A29: 操作系统（23.33%，35分）
A30: 操作系统基础 | B30: 小节得分
B31: 2
A32: 进程管理 | B32: 小节得分
B33: 16
A34: 内存管理 | B34: 小节得分
B35: 8
A36: 文件管理 | B36: 小节得分
B37: 2
A38: 输入/输出（I/O）管理 | B38: 小节得分
B39: 7
A40: 计算机网络（16.67%，25分）
...

Sheet 2018
A1: 数据结构（30%，45分）
A2: 基本概念 | B2: 小节得分
B3: 2
A4: 线性表 | B4: 小节得分
B5: 11
A6: 栈、队列和数组 | B6: 小节得分
B7: 6
A8: 树和二叉树 | B8: 小节得分
B9: 6
A10: 图 | B10: 小节得分
B11: 12
A12: 查找 | B12: 小节得分
B13: 6
A14: 排序 | B14: 小节得分
B15: 2
A16: 计算机组成原理（30%，45分）
A17: 计算机系统概述 | B17: 小节得分
B18: 2
A19: 数据的表示和运算 | B19: 小节得分
B20: 9
A21: 存储器层次结构 | B21: 小节得分
B22: 17
A23: 指令系统 | B23: 小节得分
B24: 3
A25: 中央处理器（CPU） | B25: 小节得分
B26: 2
A27: 总线和输入输出系统 | B27: 小节得分
B28: 12
A29: 操作系统（23.33%，35分）
A30: 操作系统基础 | B30: 小节得分
B31: 3
A32: 进程管理 | B32: 小节得分
B33: 15
A34: 内存管理 | B34: 小节得分
B35: 6
A36: 文件管理 | B36: 小节得分
B37: 9
A38: 输入/输出（I/O）管理 | B38: 小节得分
B39: 2
A40: 计算机网络（16.67%，25分）
...

Sheet 2017
A1: 数据结构（30%，45分）
A2: 基本概念 | B2: 小节得分
B3: 2
A4: 线性表 | B4: 小节得分
B5: 0
A6: 栈、队列和数组 | B6: 小节得分
B7: 4
A8: 树和二叉树 | B8: 小节得分
B9: 21
A10: 图 | B10: 小节得分
B11: 10
A12: 查找 | B12: 小节得分
B13: 4
A14: 排序 | B14: 小节得分
B15: 4
A16: 计算机组成原理（30%，45分）
A17: 计算机系统概述 | B17: 小节得分
B18: 2
A19: 数据的表示和运算 | B19: 小节得分
B20: 19
A21: 存储器层次结构 | B21: 小节得分
B22: 4
A23: 指令系统 | B23: 小节得分
B24: 9
A25: 中央处理器（CPU） | B25: 小节得分
B26: 5
A27: 总线和输入输出系统 | B27: 小节得分
B28: 6
A29: 操作系统（23.33%，35分）
A30: 操作系统基础 | B30: 小节得分
B31: 5.5
A32: 进程管理 | B32: 小节得分
B33: 13.5
A34: 内存管理 | B34: 小节得分
B35: 6
A36: 文件管理 | B36: 小节得分
B37: 7
A38: 输入/输出（I/O）管理 | B38: 小节得分
B39: 3
A40: 计算机网络（16.67%，25分）
...

Sheet 2016
A1: 数据结构（30%，45分）
A2: 基本概念 | B2: 小节得分
A4: 线性表 | B4: 小节得分
A6: 栈、队列和数组 | B6: 小节得分
A8: 树和二叉树 | B8: 小节得分
A10: 图 | B10: 小节得分
A12: 查找 | B12: 小节得分
A14: 排序 | B14: 小节得分
A16: 计算机组成原理（30%，45分）
A17: 计算机系统概述 | B17: 小节得分
A19: 数据的表示和运算 | B19: 小节得分
A21: 存储器层次结构 | B21: 小节得分
A23: 指令系统 | B23: 小节得分
A25: 中央处理器（CPU） | B25: 小节得分
A27: 总线和输入输出系统 | B27: 小节得分
A29: 操作系统（23.33%，35分）
A30: 操作系统基础 | B30: 小节得分
A32: 进程管理 | B32: 小节得分
A34: 内存管理 | B34: 小节得分
A36: 文件管理 | B36: 小节得分
A38: 输入/输出（I/O）管理 | B38: 小节得分
A40: 计算机网络（16.67%，25分）
A41: 计算机网络概述 | B41: 小节得分
A43: 物理层 | B43: 小节得分
A45: 数据链路层 | B45: 小节得分
A47: 网络层 | B47: 小节得分
A49: 传输层 | B49: 小节得分
A51: 应用层 | B51: 小节得分
